Workbook

Sheet RAW_DATA
A1: Job_ID | B1: Date_Collected | C1: Source_Portal | D1: Job_Title | E1: Company | F1: City | G1: Experience_Min(years) | H1: Experience_Max(years) | I1: Salary_Min(LPA) | J1: Salary_Max(LPA) | K1: Raw_Skills_Text | L1: Good_To_Have_Skills | M1: Remote_Option | N1: Company_Size | O1: SQL | P1: Python | Q1: PowerBI | R1: Tableau | S1: Excel | T1: Statistics | U1: AWS | V1: GCP | W1: NoSQL | X1: Data Modeling | Y1: Pandas | Z1: Numpy | AA1: Pyspark | AB1: Hadoop | AC1: ETL | AD1: Azure | AE1: Databricks | AF1: A/B Testing | AG1: Snowflake | AH1: Agile | AI1: Jira | AJ1: Git & Github | AK1: MIS Reporting | AL1: CI/CD | AM1: Python_pref | AN1: SQL_pref | AO1: Airflow_pref | AP1: Kafka_pref | AQ1: ML_pref | AR1: API_pref | AS1: Docker_pref | AT1: dbt_pref | AU1: AWS_pref | AV1: GCP_pref | AW1: Azure_pref | AX1: Tableau_pref | AY1: PowerBI_pref | AZ1: Employment_Type
A2: 1 | B2: 46178 | C2: LinkedIn | D2: Data Analyst | E2: Acko | F2: Bengaluru | G2: 4 | H2: 6 | I2: ND | J2: ND | K2: Amplitude, Mixpanel, Tableau, A/B Testing, SQL, Python, pandas, NumPy, Data Modelling, Star Schema, Snowflake Schema, Excel, Product Analytics, Funnel Analysis, Behavioral Segmentation | L2: ML Concepts | M2: ND | N2: Startup | O2: =IF(ISBLANK(K2),0,IF(ISNUMBER(SEARCH("sql",K2)),1,0)) -> 1 | P2: =IF(ISBLANK(K2),0,IF(ISNUMBER(SEARCH("Python",K2)),1,0)) -> 1 | Q2: =IF(ISBLANK(K2),0,IF(ISNUMBER(SEARCH("PowerBI",K2)),1,0)) -> 0 | R2: =IF(ISBLANK(K2),0,IF(ISNUMBER(SEARCH("Tableau",K2)),1,0)) -> 1 | S2: =IF(ISBLANK(K2),0,IF(ISNUMBER(SEARCH("Excel",K2)),1,0)) -> 1 | T2: =IF(ISBLANK(K2),0,IF(ISNUMBER(SEARCH("Statistics",K2)),1,0)) -> 0 | U2: =IF(ISBLANK(K2),0,IF(ISNUMBER(SEARCH("AWS",K2)),1,0)) -> 0 | V2: =IF(ISBLANK(K2),0,IF(ISNUMBER(SEARCH("GCP",K2)),1,0)) -> 0 | W2: =IF(ISBLANK(K2),0,IF(ISNUMBER(SEARCH("NoSQL",K2)),1,0)) -> 0 | X2: =IF(ISBLANK(K2),0,IF(ISNUMBER(SEARCH("Data Modeling",K2)),1,0)) -> 0 | Y2: =IF(ISBLANK(K2),0,IF(ISNUMBER(SEARCH("Pandas",K2)),1,0)) -> 1 | Z2: =IF(ISBLANK(K2),0,IF(ISNUMBER(SEARCH("Numpy",K2)),1,0)) -> 1 | AA2: =IF(ISBLANK(K2),0,IF(ISNUMBER(SEARCH("Pyspark",K2)),1,0)) -> 0 | AB2: =IF(ISBLANK(K2),0,IF(ISNUMBER(SEARCH("Hadoop",K2)),1,0)) -> 0 | AC2: =IF(ISBLANK(K2),0,IF(ISNUMBER(SEARCH("ETL",K2)),1,0)) -> 0 | AD2: =IF(ISBLANK(K2),0,IF(ISNUMBER(SEARCH("Azure",K2)),1,0)) -> 0 | AE2: =IF(ISBLANK(K2),0,IF(ISNUMBER(SEARCH("Databricks",K2)),1,0)) -> 0 | AF2: =IF(ISBLANK(K2),0,IF(ISNUMBER(SEARCH("A/B Testing",K2)),1,0)) -> 1 | AG2: =IF(ISBLANK(K2),0,IF(ISNUMBER(SEARCH("Snowflake",K2)),1,0)) -> 1 | AH2: =IF(ISBLANK(K2),0,IF(ISNUMBER(SEARCH("Agile",K2)),1,0)) -> 0 | AI2: =IF(ISBLANK(K2),0,IF(ISNUMBER(SEARCH("Jira",K2)),1,0)) -> 0 | AJ2: =IF(ISBLANK(K2),0,IF(ISNUMBER(SEARCH("Git",K2)),1,0)) -> 0 | AK2: =IF(ISBLANK(K2),0,IF(ISNUMBER(SEARCH("Reporting",K2)),1,0)) -> 0 | AL2: =AM2 -> 0 | AM2: =AN5 -> 0 | AN2: =IF(ISBLANK(L2),0,IF(ISNUMBER(SEARCH("SQL",L2)),1,0)) -> 0 | AO2: =IF(ISBLANK(L2),0,IF(ISNUMBER(SEARCH("Airflow",L2)),1,0)) -> 0 | AP2: =IF(ISBLANK(L2),0,IF(ISNUMBER(SEARCH("Kafka",L2)),1,0)) -> 0 | AQ2: =AR3 -> 0 | AR2: =IF(ISBLANK(L4),0,IF(ISNUMBER(SEARCH("API",L4)),1,0)) -> 0 | AS2: =IF(ISBLANK(L4),0,IF(ISNUMBER(SEARCH("Docker",L4)),1,0)) -> 0 | AT2: =IF(ISBLANK(L4),0,IF(ISNUMBER(SEARCH("dbt",L4)),1,0)) -> 0 | AU2: =IF(ISBLANK(L4),0,IF(ISNUMBER(SEARCH("AWS",L4)),1,0)) -> 0 | AV2: =IF(ISBLANK(L4),0,IF(ISNUMBER(SEARCH("GCP",L4)),1,0)) -> 0 | AW2: =IF(ISBLANK(L4),0,IF(ISNUMBER(SEARCH("Azure",L4)),1,0)) -> 0 | AX2: =IF(ISBLANK(M4),0,IF(ISNUMBER(SEARCH("Tableau",L4)),1,0)) -> 0 | AY2: =IF(ISBLANK(N4),0,IF(ISNUMBER(SEARCH("PowerBI",L4)),1,0)) -> 0 | AZ2: Fulltime
A3: 2 | B3: 46178 | C3: LinkedIn | D3: Data Analyst | E3: Dassault Systemes | F3: Bengaluru | G3: 3 | H3: 5 | I3: ND | J3: ND | K3: Python , Java, Oracle SQL, Adavnced Excel , BI & dashboards , Data Visulaization & KPI reporting | L3: None | M3: ND | N3: Small | O3: =IF(ISBLANK(K3),0,IF(ISNUMBER(SEARCH("sql",K3)),1,0)) -> 1 | P3: =IF(ISBLANK(K3),0,IF(ISNUMBER(SEARCH("Python",K3)),1,0)) -> 1 | Q3: =IF(ISBLANK(K3),0,IF(ISNUMBER(SEARCH("PowerBI",K3)),1,0)) -> 0 | R3: =IF(ISBLANK(K3),0,IF(ISNUMBER(SEARCH("Tableau",K3)),1,0)) -> 0 | S3: =IF(ISBLANK(K3),0,IF(ISNUMBER(SEARCH("Excel",K3)),1,0)) -> 1 | T3: =IF(ISBLANK(K3),0,IF(ISNUMBER(SEARCH("Statistics",K3)),1,0)) -> 0 | U3: =IF(ISBLANK(K3),0,IF(ISNUMBER(SEARCH("AWS",K3)),1,0)) -> 0 | V3: =IF(ISBLANK(K3),0,IF(ISNUMBER(SEARCH("GCP",K3)),1,0)) -> 0 | W3: =IF(ISBLANK(K3),0,IF(ISNUMBER(SEARCH("NoSQL",K3)),1,0)) -> 0 | X3: =IF(ISBLANK(K3),0,IF(ISNUMBER(SEARCH("Data Modeling",K3)),1,0)) -> 0 | Y3: =IF(ISBLANK(K3),0,IF(ISNUMBER(SEARCH("Pandas",K3)),1,0)) -> 0 | Z3: =IF(ISBLANK(K3),0,IF(ISNUMBER(SEARCH("Numpy",K3)),1,0)) -> 0 | AA3: =IF(ISBLANK(K3),0,IF(ISNUMBER(SEARCH("Pyspark",K3)),1,0)) -> 0 | AB3: =IF(ISBLANK(K3),0,IF(ISNUMBER(SEARCH("Hadoop",K3)),1,0)) -> 0 | AC3: =IF(ISBLANK(K3),0,IF(ISNUMBER(SEARCH("ETL",K3)),1,0)) -> 0 | AD3: =IF(ISBLANK(K3),0,IF(ISNUMBER(SEARCH("Azure",K3)),1,0)) -> 0 | AE3: =IF(ISBLANK(K3),0,IF(ISNUMBER(SEARCH("Databricks",K3)),1,0)) -> 0 | AF3: =IF(ISBLANK(K3),0,IF(ISNUMBER(SEARCH("A/B Testing",K3)),1,0)) -> 0 | AG3: =IF(ISBLANK(K3),0,IF(ISNUMBER(SEARCH("Snowflake",K3)),1,0)) -> 0 | AH3: =IF(ISBLANK(K3),0,IF(ISNUMBER(SEARCH("Agile",K3)),1,0)) -> 0 | AI3: =IF(ISBLANK(K3),0,IF(ISNUMBER(SEARCH("Jira",K3)),1,0)) -> 0 | AJ3: =IF(ISBLANK(K3),0,IF(ISNUMBER(SEARCH("Git",K3)),1,0)) -> 0 | AK3: =IF(ISBLANK(K3),0,IF(ISNUMBER(SEARCH("Reporting",K3)),1,0)) -> 1 | AL3: =IF(ISBLANK(K3),0,IF(ISNUMBER(SEARCH("CI/CD",K3)),1,0)) -> 0 | AM3: =IF(ISBLANK(L3),0,IF(ISNUMBER(SEARCH("Python",L3)),1,0)) -> 0 | AN3: =IF(ISBLANK(L3),0,IF(ISNUMBER(SEARCH("SQL",L3)),1,0)) -> 0 | AO3: =IF(ISBLANK(L3),0,IF(ISNUMBER(SEARCH("Airflow",L3)),1,0)) -> 0 | AP3: =IF(ISBLANK(L3),0,IF(ISNUMBER(SEARCH("Kafka",L3)),1,0)) -> 0 | AQ3: =IF(ISBLANK(L3),0,IF(ISNUMBER(SEARCH("ML",L3)),1,0)) -> 0 | AR3: =IF(ISBLANK(L4),0,IF(ISNUMBER(SEARCH("ML",L4)),1,0)) -> 0 | AS3: =IF(ISBLANK(L5),0,IF(ISNUMBER(SEARCH("Docker",L5)),1,0)) -> 0 | AT3: =IF(ISBLANK(L5),0,IF(ISNUMBER(SEARCH("dbt",L5)),1,0)) -> 0 | AU3: =IF(ISBLANK(L5),0,IF(ISNUMBER(SEARCH("AWS",L5)),1,0)) -> 0 | AV3: =IF(ISBLANK(L5),0,IF(ISNUMBER(SEARCH("GCP",L5)),1,0)) -> 0 | AW3: =IF(ISBLANK(L5),0,IF(ISNUMBER(SEARCH("Azure",L5)),1,0)) -> 0 | AX3: =IF(ISBLANK(M5),0,IF(ISNUMBER(SEARCH("Tableau",L5)),1,0)) -> 0 | AY3: =IF(ISBLANK(N5),0,IF(ISNUMBER(SEARCH("PowerBI",L5)),1,0)) -> 0 | AZ3: Fulltime
A4: 3 | B4: 46178 | C4: LinkedIn | D4: MIS Analyst | E4: Teamware Solutions | F4: Mumbai | G4: 3 | H4: 5 | I4: ND | J4: ND | K4: Excel, MIS Analysis and Reporting , PowerBI , MIS and SOP dovumentation | L4: None | M4: ND | N4: Small | O4: =IF(ISBLANK(K4),0,IF(ISNUMBER(SEARCH("sql",K4)),1,0)) -> 0 | P4: =IF(ISBLANK(K4),0,IF(ISNUMBER(SEARCH("Python",K4)),1,0)) -> 0 | Q4: =IF(ISBLANK(K4),0,IF(ISNUMBER(SEARCH("PowerBI",K4)),1,0)) -> 1 | R4: =IF(ISBLANK(K4),0,IF(ISNUMBER(SEARCH("Tableau",K4)),1,0)) -> 0 | S4: =IF(ISBLANK(K4),0,IF(ISNUMBER(SEARCH("Excel",K4)),1,0)) -> 1 | T4: =IF(ISBLANK(K4),0,IF(ISNUMBER(SEARCH("Statistics",K4)),1,0)) -> 0 | U4: =IF(ISBLANK(K4),0,IF(ISNUMBER(SEARCH("AWS",K4)),1,0)) -> 0 | V4: =IF(ISBLANK(K4),0,IF(ISNUMBER(SEARCH("GCP",K4)),1,0)) -> 0 | W4: =IF(ISBLANK(K4),0,IF(ISNUMBER(SEARCH("NoSQL",K4)),1,0)) -> 0 | X4: =IF(ISBLANK(K4),0,IF(ISNUMBER(SEARCH("Data Modeling",K4)),1,0)) -> 0 | Y4: =IF(ISBLANK(K4),0,IF(ISNUMBER(SEARCH("Pandas",K4)),1,0)) -> 0 | Z4: =IF(ISBLANK(K4),0,IF(ISNUMBER(SEARCH("Numpy",K4)),1,0)) -> 0 | AA4: =IF(ISBLANK(K4),0,IF(ISNUMBER(SEARCH("Pyspark",K4)),1,0)) -> 0 | AB4: =IF(ISBLANK(K4),0,IF(ISNUMBER(SEARCH("Hadoop",K4)),1,0)) -> 0 | AC4: =IF(ISBLANK(K4),0,IF(ISNUMBER(SEARCH("ETL",K4)),1,0)) -> 0 | AD4: =IF(ISBLANK(K4),0,IF(ISNUMBER(SEARCH("Azure",K4)),1,0)) -> 0 | AE4: =IF(ISBLANK(K4),0,IF(ISNUMBER(SEARCH("Databricks",K4)),1,0)) -> 0 | AF4: =IF(ISBLANK(K4),0,IF(ISNUMBER(SEARCH("A/B Testing",K4)),1,0)) -> 0 | AG4: =IF(ISBLANK(K4),0,IF(ISNUMBER(SEARCH("Snowflake",K4)),1,0)) -> 0 | AH4: =IF(ISBLANK(K4),0,IF(ISNUMBER(SEARCH("Agile",K4)),1,0)) -> 0 | AI4: =IF(ISBLANK(K4),0,IF(ISNUMBER(SEARCH("Jira",K4)),1,0)) -> 0 | AJ4: =IF(ISBLANK(K4),0,IF(ISNUMBER(SEARCH("Git",K4)),1,0)) -> 0 | AK4: =IF(ISBLANK(K4),0,IF(ISNUMBER(SEARCH("Reporting",K4)),1,0)) -> 1 | AL4: =IF(ISBLANK(K4),0,IF(ISNUMBER(SEARCH("CI/CD",K4)),1,0)) -> 0 | AM4: =IF(ISBLANK(L4),0,IF(ISNUMBER(SEARCH("Python",L4)),1,0)) -> 0 | AN4: =IF(ISBLANK(L4),0,IF(ISNUMBER(SEARCH("SQL",L4)),1,0)) -> 0 | AO4: =IF(ISBLANK(L4),0,IF(ISNUMBER(SEARCH("Airflow",L4)),1,0)) -> 0 | AP4: =IF(ISBLANK(L4),0,IF(ISNUMBER(SEARCH("Kafka",L4)),1,0)) -> 0 | AQ4: =IF(ISBLANK(L4),0,IF(ISNUMBER(SEARCH("ML",L4)),1,0)) -> 0 | AR4: =IF(ISBLANK(L5),0,IF(ISNUMBER(SEARCH("ML",L5)),1,0)) -> 0 | AS4: =IF(ISBLANK(L6),0,IF(ISNUMBER(SEARCH("Docker",L6)),1,0)) -> 0 | AT4: =IF(ISBLANK(L6),0,IF(ISNUMBER(SEARCH("dbt",L6)),1,0)) -> 0 | AU4: =IF(ISBLANK(L6),0,IF(ISNUMBER(SEARCH("AWS",L6)),1,0)) -> 0 | AV4: =IF(ISBLANK(L6),0,IF(ISNUMBER(SEARCH("GCP",L6)),1,0)) -> 0 | AW4: =IF(ISBLANK(L6),0,IF(ISNUMBER(SEARCH("Azure",L6)),1,0)) -> 0 | AX4: =IF(ISBLANK(M6),0,IF(ISNUMBER(SEARCH("Tableau",L6)),1,0)) -> 0 | AY4: =IF(ISBLANK(N6),0,IF(ISNUMBER(SEARCH("PowerBI",L6)),1,0)) -> 0 | AZ4: Fulltime
A5: 4 | B5: 46178 | C5: LinkedIn | D5: Data Engineer | E5: OptimHire | F5: Hyderabad | G5: 6 | H5: 10 | I5: ND | J5: ND | K5: Python , PySpark , Scala, Big Data processing, ETL development, Data pipelines,AWS | L5: None | M5: ND | N5: Medium | O5: =IF(ISBLANK(K5),0,IF(ISNUMBER(SEARCH("sql",K5)),1,0)) -> 0 | P5: =IF(ISBLANK(K5),0,IF(ISNUMBER(SEARCH("Python",K5)),1,0)) -> 1 | Q5: =IF(ISBLANK(K5),0,IF(ISNUMBER(SEARCH("PowerBI",K5)),1,0)) -> 0 | R5: =IF(ISBLANK(K5),0,IF(ISNUMBER(SEARCH("Tableau",K5)),1,0)) -> 0 | S5: =IF(ISBLANK(K5),0,IF(ISNUMBER(SEARCH("Excel",K5)),1,0)) -> 0 | T5: =IF(ISBLANK(K5),0,IF(ISNUMBER(SEARCH("Statistics",K5)),1,0)) -> 0 | U5: =IF(ISBLANK(K5),0,IF(ISNUMBER(SEARCH("AWS",K5)),1,0)) -> 1 | V5: =IF(ISBLANK(K5),0,IF(ISNUMBER(SEARCH("GCP",K5)),1,0)) -> 0 | W5: =IF(ISBLANK(K5),0,IF(ISNUMBER(SEARCH("NoSQL",K5)),1,0)) -> 0 | X5: =IF(ISBLANK(K5),0,IF(ISNUMBER(SEARCH("Data Modeling",K5)),1,0)) -> 0 | Y5: =IF(ISBLANK(K5),0,IF(ISNUMBER(SEARCH("Pandas",K5)),1,0)) -> 0 | Z5: =IF(ISBLANK(K5),0,IF(ISNUMBER(SEARCH("Numpy",K5)),1,0)) -> 0 | AA5: =IF(ISBLANK(K5),0,IF(ISNUMBER(SEARCH("Pyspark",K5)),1,0)) -> 1 | AB5: =IF(ISBLANK(K5),0,IF(ISNUMBER(SEARCH("Hadoop",K5)),1,0)) -> 0 | AC5: =IF(ISBLANK(K5),0,IF(ISNUMBER(SEARCH("ETL",K5)),1,0)) -> 1 | AD5: =IF(ISBLANK(K5),0,IF(ISNUMBER(SEARCH("Azure",K5)),1,0)) -> 0 | AE5: =IF(ISBLANK(K5),0,IF(ISNUMBER(SEARCH("Databricks",K5)),1,0)) -> 0 | AF5: =IF(ISBLANK(K5),0,IF(ISNUMBER(SEARCH("A/B Testing",K5)),1,0)) -> 0 | AG5: =IF(ISBLANK(K5),0,IF(ISNUMBER(SEARCH("Snowflake",K5)),1,0)) -> 0 | AH5: =IF(ISBLANK(K5),0,IF(ISNUMBER(SEARCH("Agile",K5)),1,0)) -> 0 | AI5: =IF(ISBLANK(K5),0,IF(ISNUMBER(SEARCH("Jira",K5)),1,0)) -> 0 | AJ5: =IF(ISBLANK(K5),0,IF(ISNUMBER(SEARCH("Git",K5)),1,0)) -> 0 | AK5: =IF(ISBLANK(K5),0,IF(ISNUMBER(SEARCH("Reporting",K5)),1,0)) -> 0 | AL5: =IF(ISBLANK(K5),0,IF(ISNUMBER(SEARCH("CI/CD",K5)),1,0)) -> 0 | AM5: =IF(ISBLANK(L5),0,IF(ISNUMBER(SEARCH("Python",L5)),1,0)) -> 0 | AN5: =IF(ISBLANK(L5),0,IF(ISNUMBER(SEARCH("SQL",L5)),1,0)) -> 0 | AO5: =IF(ISBLANK(L5),0,IF(ISNUMBER(SEARCH("Airflow",L5)),1,0)) -> 0 | AP5: =IF(ISBLANK(L5),0,IF(ISNUMBER(SEARCH("Kafka",L5)),1,0)) -> 0 | AQ5: =IF(ISBLANK(L5),0,IF(ISNUMBER(SEARCH("ML",L5)),1,0)) -> 0 | AR5: =IF(ISBLANK(L6),0,IF(ISNUMBER(SEARCH("ML",L6)),1,0)) -> 0 | AS5: =IF(ISBLANK(L7),0,IF(ISNUMBER(SEARCH("Docker",L7)),1,0)) -> 0 | AT5: =IF(ISBLANK(L7),0,IF(ISNUMBER(SEARCH("dbt",L7)),1,0)) -> 0 | AU5: =IF(ISBLANK(L7),0,IF(ISNUMBER(SEARCH("AWS",L7)),1,0)) -> 0 | AV5: =IF(ISBLANK(L7),0,IF(ISNUMBER(SEARCH("GCP",L7)),1,0)) -> 0 | AW5: =IF(ISBLANK(L7),0,IF(ISNUMBER(SEARCH("Azure",L7)),1,0)) -> 0 | AX5: =IF(ISBLANK(M7),0,IF(ISNUMBER(SEARCH("Tableau",L7)),1,0)) -> 0 | AY5: =IF(ISBLANK(N7),0,IF(ISNUMBER(SEARCH("PowerBI",L7)),1,0)) -> 0 | AZ5: Fulltime
A6: 5 | B6: 46178 | C6: LinkedIn | D6: BI Developer | E6: Qpact Solutions | F6: Hyderabad | G6: 5 | H6: 10 | I6: ND | J6: ND | K6: PowerBI , DAX, Python , Automation,SQl , Database management,ETL, Data visualization | L6: None | M6: Hybrid | N6: Medium | O6: =IF(ISBLANK(K6),0,IF(ISNUMBER(SEARCH("sql",K6)),1,0)) -> 1 | P6: =IF(ISBLANK(K6),0,IF(ISNUMBER(SEARCH("Python",K6)),1,0)) -> 1 | Q6: =IF(ISBLANK(K6),0,IF(ISNUMBER(SEARCH("PowerBI",K6)),1,0)) -> 1 | R6: =IF(ISBLANK(K6),0,IF(ISNUMBER(SEARCH("Tableau",K6)),1,0)) -> 0 | S6: =IF(ISBLANK(K6),0,IF(ISNUMBER(SEARCH("Excel",K6)),1,0)) -> 0 | T6: =IF(ISBLANK(K6),0,IF(ISNUMBER(SEARCH("Statistics",K6)),1,0)) -> 0 | U6: =IF(ISBLANK(K6),0,IF(ISNUMBER(SEARCH("AWS",K6)),1,0)) -> 0 | V6: =IF(ISBLANK(K6),0,IF(ISNUMBER(SEARCH("GCP",K6)),1,0)) -> 0 | W6: =IF(ISBLANK(K6),0,IF(ISNUMBER(SEARCH("NoSQL",K6)),1,0)) -> 0 | X6: =IF(ISBLANK(K6),0,IF(ISNUMBER(SEARCH("Data Modeling",K6)),1,0)) -> 0 | Y6: =IF(ISBLANK(K6),0,IF(ISNUMBER(SEARCH("Pandas",K6)),1,0)) -> 0 | Z6: =IF(ISBLANK(K6),0,IF(ISNUMBER(SEARCH("Numpy",K6)),1,0)) -> 0 | AA6: =IF(ISBLANK(K6),0,IF(ISNUMBER(SEARCH("Pyspark",K6)),1,0)) -> 0 | AB6: =IF(ISBLANK(K6),0,IF(ISNUMBER(SEARCH("Hadoop",K6)),1,0)) -> 0 | AC6: =IF(ISBLANK(K6),0,IF(ISNUMBER(SEARCH("ETL",K6)),1,0)) -> 1 | AD6: =IF(ISBLANK(K6),0,IF(ISNUMBER(SEARCH("Azure",K6)),1,0)) -> 0 | AE6: =IF(ISBLANK(K6),0,IF(ISNUMBER(SEARCH("Databricks",K6)),1,0)) -> 0 | AF6: =IF(ISBLANK(K6),0,IF(ISNUMBER(SEARCH("A/B Testing",K6)),1,0)) -> 0 | AG6: =IF(ISBLANK(K6),0,IF(ISNUMBER(SEARCH("Snowflake",K6)),1,0)) -> 0 | AH6: =IF(ISBLANK(K6),0,IF(ISNUMBER(SEARCH("Agile",K6)),1,0)) -> 0 | AI6: =IF(ISBLANK(K6),0,IF(ISNUMBER(SEARCH("Jira",K6)),1,0)) -> 0 | AJ6: =IF(ISBLANK(K6),0,IF(ISNUMBER(SEARCH("Git",K6)),1,0)) -> 0 | AK6: =IF(ISBLANK(K6),0,IF(ISNUMBER(SEARCH("Reporting",K6)),1,0)) -> 0 | AL6: =IF(ISBLANK(K6),0,IF(ISNUMBER(SEARCH("CI/CD",K6)),1,0)) -> 0 | AM6: =IF(ISBLANK(L6),0,IF(ISNUMBER(SEARCH("Python",L6)),1,0)) -> 0 | AN6: =IF(ISBLANK(L6),0,IF(ISNUMBER(SEARCH("SQL",L6)),1,0)) -> 0 | AO6: =IF(ISBLANK(L6),0,IF(ISNUMBER(SEARCH("Airflow",L6)),1,0)) -> 0 | AP6: =IF(ISBLANK(L6),0,IF(ISNUMBER(SEARCH("Kafka",L6)),1,0)) -> 0 | AQ6: =IF(ISBLANK(L6),0,IF(ISNUMBER(SEARCH("ML",L6)),1,0)) -> 0 | AR6: =IF(ISBLANK(L7),0,IF(ISNUMBER(SEARCH("ML",L7)),1,0)) -> 0 | AS6: =IF(ISBLANK(L8),0,IF(ISNUMBER(SEARCH("Docker",L8)),1,0)) -> 0 | AT6: =IF(ISBLANK(L8),0,IF(ISNUMBER(SEARCH("dbt",L8)),1,0)) -> 0 | AU6: =IF(ISBLANK(L8),0,IF(ISNUMBER(SEARCH("AWS",L8)),1,0)) -> 0 | AV6: =IF(ISBLANK(L8),0,IF(ISNUMBER(SEARCH("GCP",L8)),1,0)) -> 0 | AW6: =IF(ISBLANK(L8),0,IF(ISNUMBER(SEARCH("Azure",L8)),1,0)) -> 0 | AX6: =IF(ISBLANK(M8),0,IF(ISNUMBER(SEARCH("Tableau",L8)),1,0)) -> 0 | AY6: =IF(ISBLANK(N8),0,IF(ISNUMBER(SEARCH("PowerBI",L8)),1,0)) -> 0 | AZ6: Fulltime
A7: 6 | B7: 46178 | C7: LinkedIn | D7: Data Analyst | E7: GreedyGame | F7: Bengaluru | G7: 2 | H7: 4 | I7: ND | J7: ND | K7: Python , R , Numpy , Pandas, SQL , PowerBI , Looker Studio, BigQuery, Web and App analytics | L7: Kafka(exposure),A/B testing , Tensorflow or HuggingFace(familiarity) | M7: On-site | N7: Startup | O7: =IF(ISBLANK(K7),0,IF(ISNUMBER(SEARCH("sql",K7)),1,0)) -> 1 | P7: =IF(ISBLANK(K7),0,IF(ISNUMBER(SEARCH("Python",K7)),1,0)) -> 1 | Q7: =IF(ISBLANK(K7),0,IF(ISNUMBER(SEARCH("PowerBI",K7)),1,0)) -> 1 | R7: =IF(ISBLANK(K7),0,IF(ISNUMBER(SEARCH("Tableau",K7)),1,0)) -> 0 | S7: =IF(ISBLANK(K7),0,IF(ISNUMBER(SEARCH("Excel",K7)),1,0)) -> 0 | T7: =IF(ISBLANK(K7),0,IF(ISNUMBER(SEARCH("Statistics",K7)),1,0)) -> 0 | U7: =IF(ISBLANK(K7),0,IF(ISNUMBER(SEARCH("AWS",K7)),1,0)) -> 0 | V7: =IF(ISBLANK(K7),0,IF(ISNUMBER(SEARCH("GCP",K7)),1,0)) -> 0 | W7: =IF(ISBLANK(K7),0,IF(ISNUMBER(SEARCH("NoSQL",K7)),1,0)) -> 0 | X7: =IF(ISBLANK(K7),0,IF(ISNUMBER(SEARCH("Data Modeling",K7)),1,0)) -> 0 | Y7: =IF(ISBLANK(K7),0,IF(ISNUMBER(SEARCH("Pandas",K7)),1,0)) -> 1 | Z7: =IF(ISBLANK(K7),0,IF(ISNUMBER(SEARCH("Numpy",K7)),1,0)) -> 1 | AA7: =IF(ISBLANK(K7),0,IF(ISNUMBER(SEARCH("Pyspark",K7)),1,0)) -> 0 | AB7: =IF(ISBLANK(K7),0,IF(ISNUMBER(SEARCH("Hadoop",K7)),1,0)) -> 0 | AC7: =IF(ISBLANK(K7),0,IF(ISNUMBER(SEARCH("ETL",K7)),1,0)) -> 0 | AD7: =IF(ISBLANK(K7),0,IF(ISNUMBER(SEARCH("Azure",K7)),1,0)) -> 0 | AE7: =IF(ISBLANK(K7),0,IF(ISNUMBER(SEARCH("Databricks",K7)),1,0)) -> 0 | AF7: =IF(ISBLANK(K7),0,IF(ISNUMBER(SEARCH("A/B Testing",K7)),1,0)) -> 0 | AG7: =IF(ISBLANK(K7),0,IF(ISNUMBER(SEARCH("Snowflake",K7)),1,0)) -> 0 | AH7: =IF(ISBLANK(K7),0,IF(ISNUMBER(SEARCH("Agile",K7)),1,0)) -> 0 | AI7: =IF(ISBLANK(K7),0,IF(ISNUMBER(SEARCH("Jira",K7)),1,0)) -> 0 | AJ7: =IF(ISBLANK(K7),0,IF(ISNUMBER(SEARCH("Git",K7)),1,0)) -> 0 | AK7: =IF(ISBLANK(K7),0,IF(ISNUMBER(SEARCH("Reporting",K7)),1,0)) -> 0 | AL7: =IF(ISBLANK(K7),0,IF(ISNUMBER(SEARCH("CI/CD",K7)),1,0)) -> 0 | AM7: =IF(ISBLANK(L7),0,IF(ISNUMBER(SEARCH("Python",L7)),1,0)) -> 0 | AN7: =IF(ISBLANK(L7),0,IF(ISNUMBER(SEARCH("SQL",L7)),1,0)) -> 0 | AO7: =IF(ISBLANK(L7),0,IF(ISNUMBER(SEARCH("Airflow",L7)),1,0)) -> 0 | AP7: =IF(ISBLANK(L7),0,IF(ISNUMBER(SEARCH("Kafka",L7)),1,0)) -> 1 | AQ7: =IF(ISBLANK(L7),0,IF(ISNUMBER(SEARCH("ML",L7)),1,0)) -> 0 | AR7: =IF(ISBLANK(L8),0,IF(ISNUMBER(SEARCH("ML",L8)),1,0)) -> 0 | AS7: =IF(ISBLANK(L9),0,IF(ISNUMBER(SEARCH("Docker",L9)),1,0)) -> 0 | AT7: =IF(ISBLANK(L9),0,IF(ISNUMBER(SEARCH("dbt",L9)),1,0)) -> 0 | AU7: =IF(ISBLANK(L9),0,IF(ISNUMBER(SEARCH("AWS",L9)),1,0)) -> 0 | AV7: =IF(ISBLANK(L9),0,IF(ISNUMBER(SEARCH("GCP",L9)),1,0)) -> 0 | AW7: =IF(ISBLANK(L9),0,IF(ISNUMBER(SEARCH("Azure",L9)),1,0)) -> 0 | AX7: =IF(ISBLANK(M9),0,IF(ISNUMBER(SEARCH("Tableau",L9)),1,0)) -> 0 | AY7: =IF(ISBLANK(N9),0,IF(ISNUMBER(SEARCH("PowerBI",L9)),1,0)) -> 0 | AZ7: Fulltime
A8: 7 | B8: 46178 | C8: LinkedIn | D8: MIS Analyst | E8: Kapiva | F8: Bengaluru | G8: ND | H8: ND | I8: ND | J8: ND | K8: Excel , SQL | L8: None | M8: On-site | N8: Startup | O8: =IF(ISBLANK(K8),0,IF(ISNUMBER(SEARCH("sql",K8)),1,0)) -> 1 | P8: =IF(ISBLANK(K8),0,IF(ISNUMBER(SEARCH("Python",K8)),1,0)) -> 0 | Q8: =IF(ISBLANK(K8),0,IF(ISNUMBER(SEARCH("PowerBI",K8)),1,0)) -> 0 | R8: =IF(ISBLANK(K8),0,IF(ISNUMBER(SEARCH("Tableau",K8)),1,0)) -> 0 | S8: =IF(ISBLANK(K8),0,IF(ISNUMBER(SEARCH("Excel",K8)),1,0)) -> 1 | T8: =IF(ISBLANK(K8),0,IF(ISNUMBER(SEARCH("Statistics",K8)),1,0)) -> 0 | U8: =IF(ISBLANK(K8),0,IF(ISNUMBER(SEARCH("AWS",K8)),1,0)) -> 0 | V8: =IF(ISBLANK(K8),0,IF(ISNUMBER(SEARCH("GCP",K8)),1,0)) -> 0 | W8: =IF(ISBLANK(K8),0,IF(ISNUMBER(SEARCH("NoSQL",K8)),1,0)) -> 0 | X8: =IF(ISBLANK(K8),0,IF(ISNUMBER(SEARCH("Data Modeling",K8)),1,0)) -> 0 | Y8: =IF(ISBLANK(K8),0,IF(ISNUMBER(SEARCH("Pandas",K8)),1,0)) -> 0 | Z8: =IF(ISBLANK(K8),0,IF(ISNUMBER(SEARCH("Numpy",K8)),1,0)) -> 0 | AA8: =IF(ISBLANK(K8),0,IF(ISNUMBER(SEARCH("Pyspark",K8)),1,0)) -> 0 | AB8: =IF(ISBLANK(K8),0,IF(ISNUMBER(SEARCH("Hadoop",K8)),1,0)) -> 0 | AC8: =IF(ISBLANK(K8),0,IF(ISNUMBER(SEARCH("ETL",K8)),1,0)) -> 0 | AD8: =IF(ISBLANK(K8),0,IF(ISNUMBER(SEARCH("Azure",K8)),1,0)) -> 0 | AE8: =IF(ISBLANK(K8),0,IF(ISNUMBER(SEARCH("Databricks",K8)),1,0)) -> 0 | AF8: =IF(ISBLANK(K8),0,IF(ISNUMBER(SEARCH("A/B Testing",K8)),1,0)) -> 0 | AG8: =IF(ISBLANK(K8),0,IF(ISNUMBER(SEARCH("Snowflake",K8)),1,0)) -> 0 | AH8: =IF(ISBLANK(K8),0,IF(ISNUMBER(SEARCH("Agile",K8)),1,0)) -> 0 | AI8: =IF(ISBLANK(K8),0,IF(ISNUMBER(SEARCH("Jira",K8)),1,0)) -> 0 | AJ8: =IF(ISBLANK(K8),0,IF(ISNUMBER(SEARCH("Git",K8)),1,0)) -> 0 | AK8: =IF(ISBLANK(K8),0,IF(ISNUMBER(SEARCH("Reporting",K8)),1,0)) -> 0 | AL8: =IF(ISBLANK(K8),0,IF(ISNUMBER(SEARCH("CI/CD",K8)),1,0)) -> 0 | AM8: =IF(ISBLANK(L8),0,IF(ISNUMBER(SEARCH("Python",L8)),1,0)) -> 0 | AN8: =IF(ISBLANK(L8),0,IF(ISNUMBER(SEARCH("SQL",L8)),1,0)) -> 0 | AO8: =IF(ISBLANK(L8),0,IF(ISNUMBER(SEARCH("Airflow",L8)),1,0)) -> 0 | AP8: =IF(ISBLANK(L8),0,IF(ISNUMBER(SEARCH("Kafka",L8)),1,0)) -> 0 | AQ8: =IF(ISBLANK(L8),0,IF(ISNUMBER(SEARCH("ML",L8)),1,0)) -> 0 | AR8: =IF(ISBLANK(L9),0,IF(ISNUMBER(SEARCH("ML",L9)),1,0)) -> 0 | AS8: =IF(ISBLANK(L10),0,IF(ISNUMBER(SEARCH("Docker",L10)),1,0)) -> 0 | AT8: =IF(ISBLANK(L10),0,IF(ISNUMBER(SEARCH("dbt",L10)),1,0)) -> 0 | AU8: =IF(ISBLANK(L10),0,IF(ISNUMBER(SEARCH("AWS",L10)),1,0)) -> 0 | AV8: =IF(ISBLANK(L10),0,IF(ISNUMBER(SEARCH("GCP",L10)),1,0)) -> 0 | AW8: =IF(ISBLANK(L10),0,IF(ISNUMBER(SEARCH("Azure",L10)),1,0)) -> 0 | AX8: =IF(ISBLANK(M10),0,IF(ISNUMBER(SEARCH("Tableau",L10)),1,0)) -> 0 | AY8: =IF(ISBLANK(N10),0,IF(ISNUMBER(SEARCH("PowerBI",L10)),1,0)) -> 0 | AZ8: Fulltime
A9: 8 | B9: 46178 | C9: LinkedIn | D9: Data Analyst | E9: Optum India | F9: Noida | G9: 3 | H9: None | I9: ND | J9: ND | K9: Python , PySpark , Hive, SQL , Cloud Platforms, Analytics Pipelines | L9: CMS datasets such as MMR/MOR/EDPS , Medicare risk adjustment | M9: On-site | N9: Large | O9: =IF(ISBLANK(K9),0,IF(ISNUMBER(SEARCH("sql",K9)),1,0)) -> 1 | P9: =IF(ISBLANK(K9),0,IF(ISNUMBER(SEARCH("Python",K9)),1,0)) -> 1 | Q9: =IF(ISBLANK(K9),0,IF(ISNUMBER(SEARCH("PowerBI",K9)),1,0)) -> 0 | R9: =IF(ISBLANK(K9),0,IF(ISNUMBER(SEARCH("Tableau",K9)),1,0)) -> 0 | S9: =IF(ISBLANK(K9),0,IF(ISNUMBER(SEARCH("Excel",K9)),1,0)) -> 0 | T9: =IF(ISBLANK(K9),0,IF(ISNUMBER(SEARCH("Statistics",K9)),1,0)) -> 0 | U9: =IF(ISBLANK(K9),0,IF(ISNUMBER(SEARCH("AWS",K9)),1,0)) -> 0 | V9: =IF(ISBLANK(K9),0,IF(ISNUMBER(SEARCH("GCP",K9)),1,0)) -> 0 | W9: =IF(ISBLANK(K9),0,IF(ISNUMBER(SEARCH("NoSQL",K9)),1,0)) -> 0 | X9: =IF(ISBLANK(K9),0,IF(ISNUMBER(SEARCH("Data Modeling",K9)),1,0)) -> 0 | Y9: =IF(ISBLANK(K9),0,IF(ISNUMBER(SEARCH("Pandas",K9)),1,0)) -> 0 | Z9: =IF(ISBLANK(K9),0,IF(ISNUMBER(SEARCH("Numpy",K9)),1,0)) -> 0 | AA9: =IF(ISBLANK(K9),0,IF(ISNUMBER(SEARCH("Pyspark",K9)),1,0)) -> 1 | AB9: =IF(ISBLANK(K9),0,IF(ISNUMBER(SEARCH("Hadoop",K9)),1,0)) -> 0 | AC9: =IF(ISBLANK(K9),0,IF(ISNUMBER(SEARCH("ETL",K9)),1,0)) -> 0 | AD9: =IF(ISBLANK(K9),0,IF(ISNUMBER(SEARCH("Azure",K9)),1,0)) -> 0 | AE9: =IF(ISBLANK(K9),0,IF(ISNUMBER(SEARCH("Databricks",K9)),1,0)) -> 0 | AF9: =IF(ISBLANK(K9),0,IF(ISNUMBER(SEARCH("A/B Testing",K9)),1,0)) -> 0 | AG9: =IF(ISBLANK(K9),0,IF(ISNUMBER(SEARCH("Snowflake",K9)),1,0)) -> 0 | AH9: =IF(ISBLANK(K9),0,IF(ISNUMBER(SEARCH("Agile",K9)),1,0)) -> 0 | AI9: =IF(ISBLANK(K9),0,IF(ISNUMBER(SEARCH("Jira",K9)),1,0)) -> 0 | AJ9: =IF(ISBLANK(K9),0,IF(ISNUMBER(SEARCH("Git",K9)),1,0)) -> 0 | AK9: =IF(ISBLANK(K9),0,IF(ISNUMBER(SEARCH("Reporting",K9)),1,0)) -> 0 | AL9: =IF(ISBLANK(K9),0,IF(ISNUMBER(SEARCH("CI/CD",K9)),1,0)) -> 0 | AM9: =IF(ISBLANK(L9),0,IF(ISNUMBER(SEARCH("Python",L9)),1,0)) -> 0 | AN9: =IF(ISBLANK(L9),0,IF(ISNUMBER(SEARCH("SQL",L9)),1,0)) -> 0 | AO9: =IF(ISBLANK(L9),0,IF(ISNUMBER(SEARCH("Airflow",L9)),1,0)) -> 0 | AP9: =IF(ISBLANK(L9),0,IF(ISNUMBER(SEARCH("Kafka",L9)),1,0)) -> 0 | AQ9: =IF(ISBLANK(L9),0,IF(ISNUMBER(SEARCH("ML",L9)),1,0)) -> 0 | AR9: =IF(ISBLANK(L10),0,IF(ISNUMBER(SEARCH("ML",L10)),1,0)) -> 0 | AS9: =IF(ISBLANK(L11),0,IF(ISNUMBER(SEARCH("Docker",L11)),1,0)) -> 0 | AT9: =IF(ISBLANK(L11),0,IF(ISNUMBER(SEARCH("dbt",L11)),1,0)) -> 0 | AU9: =IF(ISBLANK(L11),0,IF(ISNUMBER(SEARCH("AWS",L11)),1,0)) -> 0 | AV9: =IF(ISBLANK(L11),0,IF(ISNUMBER(SEARCH("GCP",L11)),1,0)) -> 0 | AW9: =IF(ISBLANK(L11),0,IF(ISNUMBER(SEARCH("Azure",L11)),1,0)) -> 0 | AX9: =IF(ISBLANK(M11),0,IF(ISNUMBER(SEARCH("Tableau",L11)),1,0)) -> 0 | AY9: =IF(ISBLANK(N11),0,IF(ISNUMBER(SEARCH("PowerBI",L11)),1,0)) -> 0 | AZ9: Fulltime
A10: 9 | B10: 46178 | C10: LinkedIn | D10: Data Analyst | E10: Everbridge | F10: Bengaluru | G10: 2 | H10: 5 | I10: ND | J10: ND | K10: SQL , Snowflake, BigQuery, Redshift , Azure Synapse, Tableau , PowerBI, dbt, AWS Quicksight | L10: ETL Pipelines , Python, APIs,Git, AI analytics Tools, Sharepoint | M10: On-site | N10: Large | O10: =IF(ISBLANK(K10),0,IF(ISNUMBER(SEARCH("sql",K10)),1,0)) -> 1 | P10: =IF(ISBLANK(K10),0,IF(ISNUMBER(SEARCH("Python",K10)),1,0)) -> 0 | Q10: =IF(ISBLANK(K10),0,IF(ISNUMBER(SEARCH("PowerBI",K10)),1,0)) -> 1 | R10: =IF(ISBLANK(K10),0,IF(ISNUMBER(SEARCH("Tableau",K10)),1,0)) -> 1 | S10: =IF(ISBLANK(K10),0,IF(ISNUMBER(SEARCH("Excel",K10)),1,0)) -> 0 | T10: =IF(ISBLANK(K10),0,IF(ISNUMBER(SEARCH("Statistics",K10)),1,0)) -> 0 | U10: =IF(ISBLANK(K10),0,IF(ISNUMBER(SEARCH("AWS",K10)),1,0)) -> 1 | V10: =IF(ISBLANK(K10),0,IF(ISNUMBER(SEARCH("GCP",K10)),1,0)) -> 0 | W10: =IF(ISBLANK(K10),0,IF(ISNUMBER(SEARCH("NoSQL",K10)),1,0)) -> 0 | X10: =IF(ISBLANK(K10),0,IF(ISNUMBER(SEARCH("Data Modeling",K10)),1,0)) -> 0 | Y10: =IF(ISBLANK(K10),0,IF(ISNUMBER(SEARCH("Pandas",K10)),1,0)) -> 0 | Z10: =IF(ISBLANK(K10),0,IF(ISNUMBER(SEARCH("Numpy",K10)),1,0)) -> 0 | AA10: =IF(ISBLANK(K10),0,IF(ISNUMBER(SEARCH("Pyspark",K10)),1,0)) -> 0 | AB10: =IF(ISBLANK(K10),0,IF(ISNUMBER(SEARCH("Hadoop",K10)),1,0)) -> 0 | AC10: =IF(ISBLANK(K10),0,IF(ISNUMBER(SEARCH("ETL",K10)),1,0)) -> 0 | AD10: =IF(ISBLANK(K10),0,IF(ISNUMBER(SEARCH("Azure",K10)),1,0)) -> 1 | AE10: =IF(ISBLANK(K10),0,IF(ISNUMBER(SEARCH("Databricks",K10)),1,0)) -> 0 | AF10: =IF(ISBLANK(K10),0,IF(ISNUMBER(SEARCH("A/B Testing",K10)),1,0)) -> 0 | AG10: =IF(ISBLANK(K10),0,IF(ISNUMBER(SEARCH("Snowflake",K10)),1,0)) -> 1 | AH10: =IF(ISBLANK(K10),0,IF(ISNUMBER(SEARCH("Agile",K10)),1,0)) -> 0 | AI10: =IF(ISBLANK(K10),0,IF(ISNUMBER(SEARCH("Jira",K10)),1,0)) -> 0 | AJ10: =IF(ISBLANK(K10),0,IF(ISNUMBER(SEARCH("Git",K10)),1,0)) -> 0 | AK10: =IF(ISBLANK(K10),0,IF(ISNUMBER(SEARCH("Reporting",K10)),1,0)) -> 0 | AL10: =IF(ISBLANK(K10),0,IF(ISNUMBER(SEARCH("CI/CD",K10)),1,0)) -> 0 | AM10: =IF(ISBLANK(L10),0,IF(ISNUMBER(SEARCH("Python",L10)),1,0)) -> 1 | AN10: =IF(ISBLANK(L10),0,IF(ISNUMBER(SEARCH("SQL",L10)),1,0)) -> 0 | AO10: =IF(ISBLANK(L10),0,IF(ISNUMBER(SEARCH("Airflow",L10)),1,0)) -> 0 | AP10: =IF(ISBLANK(L10),0,IF(ISNUMBER(SEARCH("Kafka",L10)),1,0)) -> 0 | AQ10: =IF(ISBLANK(L10),0,IF(ISNUMBER(SEARCH("ML",L10)),1,0)) -> 0 | AR10: =IF(ISBLANK(L11),0,IF(ISNUMBER(SEARCH("ML",L11)),1,0)) -> 0 | AS10: =IF(ISBLANK(L12),0,IF(ISNUMBER(SEARCH("Docker",L12)),1,0)) -> 0 | AT10: =IF(ISBLANK(L12),0,IF(ISNUMBER(SEARCH("dbt",L12)),1,0)) -> 0 | AU10: =IF(ISBLANK(L12),0,IF(ISNUMBER(SEARCH("AWS",L12)),1,0)) -> 0 | AV10: =IF(ISBLANK(L12),0,IF(ISNUMBER(SEARCH("GCP",L12)),1,0)) -> 0 | AW10: =IF(ISBLANK(L12),0,IF(ISNUMBER(SEARCH("Azure",L12)),1,0)) -> 0 | AX10: =IF(ISBLANK(M12),0,IF(ISNUMBER(SEARCH("Tableau",L12)),1,0)) -> 0 | AY10: =IF(ISBLANK(N12),0,IF(ISNUMBER(SEARCH("PowerBI",L12)),1,0)) -> 0 | AZ10: Fulltime
A11: 10 | B11: 46178 | C11: LinkedIn | D11: Business Analyst | E11: Aditya Birla Capital | F11: Mumbai | G11: ND | H11: ND | I11: ND | J11: ND | K11: PowerBI , DAX , Excel , R,Python , Databricks | L11: None | M11: On-site | N11: Large | O11: =IF(ISBLANK(K11),0,IF(ISNUMBER(SEARCH("sql",K11)),1,0)) -> 0 | P11: =IF(ISBLANK(K11),0,IF(ISNUMBER(SEARCH("Python",K11)),1,0)) -> 1 | Q11: =IF(ISBLANK(K11),0,IF(ISNUMBER(SEARCH("PowerBI",K11)),1,0)) -> 1 | R11: =IF(ISBLANK(K11),0,IF(ISNUMBER(SEARCH("Tableau",K11)),1,0)) -> 0 | S11: =IF(ISBLANK(K11),0,IF(ISNUMBER(SEARCH("Excel",K11)),1,0)) -> 1 | T11: =IF(ISBLANK(K11),0,IF(ISNUMBER(SEARCH("Statistics",K11)),1,0)) -> 0 | U11: =IF(ISBLANK(K11),0,IF(ISNUMBER(SEARCH("AWS",K11)),1,0)) -> 0 | V11: =IF(ISBLANK(K11),0,IF(ISNUMBER(SEARCH("GCP",K11)),1,0)) -> 0 | W11: =IF(ISBLANK(K11),0,IF(ISNUMBER(SEARCH("NoSQL",K11)),1,0)) -> 0 | X11: =IF(ISBLANK(K11),0,IF(ISNUMBER(SEARCH("Data Modeling",K11)),1,0)) -> 0 | Y11: =IF(ISBLANK(K11),0,IF(ISNUMBER(SEARCH("Pandas",K11)),1,0)) -> 0 | Z11: =IF(ISBLANK(K11),0,IF(ISNUMBER(SEARCH("Numpy",K11)),1,0)) -> 0 | AA11: =IF(ISBLANK(K11),0,IF(ISNUMBER(SEARCH("Pyspark",K11)),1,0)) -> 0 | AB11: =IF(ISBLANK(K11),0,IF(ISNUMBER(SEARCH("Hadoop",K11)),1,0)) -> 0 | AC11: =IF(ISBLANK(K11),0,IF(ISNUMBER(SEARCH("ETL",K11)),1,0)) -> 0 | AD11: =IF(ISBLANK(K11),0,IF(ISNUMBER(SEARCH("Azure",K11)),1,0)) -> 0 | AE11: =IF(ISBLANK(K11),0,IF(ISNUMBER(SEARCH("Databricks",K11)),1,0)) -> 1 | AF11: =IF(ISBLANK(K11),0,IF(ISNUMBER(SEARCH("A/B Testing",K11)),1,0)) -> 0 | AG11: =IF(ISBLANK(K11),0,IF(ISNUMBER(SEARCH("Snowflake",K11)),1,0)) -> 0 | AH11: =IF(ISBLANK(K11),0,IF(ISNUMBER(SEARCH("Agile",K11)),1,0)) -> 0 | AI11: =IF(ISBLANK(K11),0,IF(ISNUMBER(SEARCH("Jira",K11)),1,0)) -> 0 | AJ11: =IF(ISBLANK(K11),0,IF(ISNUMBER(SEARCH("Git",K11)),1,0)) -> 0 | AK11: =IF(ISBLANK(K11),0,IF(ISNUMBER(SEARCH("Reporting",K11)),1,0)) -> 0 | AL11: =IF(ISBLANK(K11),0,IF(ISNUMBER(SEARCH("CI/CD",K11)),1,0)) -> 0 | AM11: =IF(ISBLANK(L11),0,IF(ISNUMBER(SEARCH("Python",L11)),1,0)) -> 0 | AN11: =IF(ISBLANK(L11),0,IF(ISNUMBER(SEARCH("SQL",L11)),1,0)) -> 0 | AO11: =IF(ISBLANK(L11),0,IF(ISNUMBER(SEARCH("Airflow",L11)),1,0)) -> 0 | AP11: =IF(ISBLANK(L11),0,IF(ISNUMBER(SEARCH("Kafka",L11)),1,0)) -> 0 | AQ11: =IF(ISBLANK(L11),0,IF(ISNUMBER(SEARCH("ML",L11)),1,0)) -> 0 | AR11: =IF(ISBLANK(L12),0,IF(ISNUMBER(SEARCH("ML",L12)),1,0)) -> 0 | AS11: =IF(ISBLANK(L13),0,IF(ISNUMBER(SEARCH("Docker",L13)),1,0)) -> 0 | AT11: =IF(ISBLANK(L13),0,IF(ISNUMBER(SEARCH("dbt",L13)),1,0)) -> 0 | AU11: =IF(ISBLANK(L13),0,IF(ISNUMBER(SEARCH("AWS",L13)),1,0)) -> 0 | AV11: =IF(ISBLANK(L13),0,IF(ISNUMBER(SEARCH("GCP",L13)),1,0)) -> 0 | AW11: =IF(ISBLANK(L13),0,IF(ISNUMBER(SEARCH("Azure",L13)),1,0)) -> 0 | AX11: =IF(ISBLANK(M13),0,IF(ISNUMBER(SEARCH("Tableau",L13)),1,0)) -> 0 | AY11: =IF(ISBLANK(N13),0,IF(ISNUMBER(SEARCH("PowerBI",L13)),1,0)) -> 0 | AZ11: Fulltime
A12: 11 | B12: 46178 | C12: LinkedIn | D12: Data Analyst | E12: Google | F12: Hyderabad | G12: 2 | H12: ND | I12: ND | J12: ND | K12: SQL, Python, R | L12: C++, Machine Learning(familarity), Risk Analysis | M12: On-site | N12: Large | O12: =IF(ISBLANK(K12),0,IF(ISNUMBER(SEARCH("sql",K12)),1,0)) -> 1 | P12: =IF(ISBLANK(K12),0,IF(ISNUMBER(SEARCH("Python",K12)),1,0)) -> 1 | Q12: =IF(ISBLANK(K12),0,IF(ISNUMBER(SEARCH("PowerBI",K12)),1,0)) -> 0 | R12: =IF(ISBLANK(K12),0,IF(ISNUMBER(SEARCH("Tableau",K12)),1,0)) -> 0 | S12: =IF(ISBLANK(K12),0,IF(ISNUMBER(SEARCH("Excel",K12)),1,0)) -> 0 | T12: =IF(ISBLANK(K12),0,IF(ISNUMBER(SEARCH("Statistics",K12)),1,0)) -> 0 | U12: =IF(ISBLANK(K12),0,IF(ISNUMBER(SEARCH("AWS",K12)),1,0)) -> 0 | V12: =IF(ISBLANK(K12),0,IF(ISNUMBER(SEARCH("GCP",K12)),1,0)) -> 0 | W12: =IF(ISBLANK(K12),0,IF(ISNUMBER(SEARCH("NoSQL",K12)),1,0)) -> 0 | X12: =IF(ISBLANK(K12),0,IF(ISNUMBER(SEARCH("Data Modeling",K12)),1,0)) -> 0 | Y12: =IF(ISBLANK(K12),0,IF(ISNUMBER(SEARCH("Pandas",K12)),1,0)) -> 0 | Z12: =IF(ISBLANK(K12),0,IF(ISNUMBER(SEARCH("Numpy",K12)),1,0)) -> 0 | AA12: =IF(ISBLANK(K12),0,IF(ISNUMBER(SEARCH("Pyspark",K12)),1,0)) -> 0 | AB12: =IF(ISBLANK(K12),0,IF(ISNUMBER(SEARCH("Hadoop",K12)),1,0)) -> 0 | AC12: =IF(ISBLANK(K12),0,IF(ISNUMBER(SEARCH("ETL",K12)),1,0)) -> 0 | AD12: =IF(ISBLANK(K12),0,IF(ISNUMBER(SEARCH("Azure",K12)),1,0)) -> 0 | AE12: =IF(ISBLANK(K12),0,IF(ISNUMBER(SEARCH("Databricks",K12)),1,0)) -> 0 | AF12: =IF(ISBLANK(K12),0,IF(ISNUMBER(SEARCH("A/B Testing",K12)),1,0)) -> 0 | AG12: =IF(ISBLANK(K12),0,IF(ISNUMBER(SEARCH("Snowflake",K12)),1,0)) -> 0 | AH12: =IF(ISBLANK(K12),0,IF(ISNUMBER(SEARCH("Agile",K12)),1,0)) -> 0 | AI12: =IF(ISBLANK(K12),0,IF(ISNUMBER(SEARCH("Jira",K12)),1,0)) -> 0 | AJ12: =IF(ISBLANK(K12),0,IF(ISNUMBER(SEARCH("Git",K12)),1,0)) -> 0 | AK12: =IF(ISBLANK(K12),0,IF(ISNUMBER(SEARCH("Reporting",K12)),1,0)) -> 0 | AL12: =IF(ISBLANK(K12),0,IF(ISNUMBER(SEARCH("CI/CD",K12)),1,0)) -> 0 | AM12: =IF(ISBLANK(L12),0,IF(ISNUMBER(SEARCH("Python",L12)),1,0)) -> 0 | AN12: =IF(ISBLANK(L12),0,IF(ISNUMBER(SEARCH("SQL",L12)),1,0)) -> 0 | AO12: =IF(ISBLANK(L12),0,IF(ISNUMBER(SEARCH("Airflow",L12)),1,0)) -> 0 | AP12: =IF(ISBLANK(L12),0,IF(ISNUMBER(SEARCH("Kafka",L12)),1,0)) -> 0 | AQ12: =IF(ISBLANK(L12),0,IF(ISNUMBER(SEARCH("ML",L12)),1,0)) -> 0 | AR12: =IF(ISBLANK(L13),0,IF(ISNUMBER(SEARCH("ML",L13)),1,0)) -> 0 | AS12: =IF(ISBLANK(L14),0,IF(ISNUMBER(SEARCH("Docker",L14)),1,0)) -> 0 | AT12: =IF(ISBLANK(L14),0,IF(ISNUMBER(SEARCH("dbt",L14)),1,0)) -> 0 | AU12: =IF(ISBLANK(L14),0,IF(ISNUMBER(SEARCH("AWS",L14)),1,0)) -> 0 | AV12: =IF(ISBLANK(L14),0,IF(ISNUMBER(SEARCH("GCP",L14)),1,0)) -> 0 | AW12: =IF(ISBLANK(L14),0,IF(ISNUMBER(SEARCH("Azure",L14)),1,0)) -> 1 | AX12: =IF(ISBLANK(M14),0,IF(ISNUMBER(SEARCH("Tableau",L14)),1,0)) -> 0 | AY12: =IF(ISBLANK(N14),0,IF(ISNUMBER(SEARCH("PowerBI",L14)),1,0)) -> 0 | AZ12: Fulltime
A13: 12 | B13: 46178 | C13: LinkedIn | D13: Data Analyst | E13: Persistent Systems | F13: Pune | G13: 5 | H13: 8 | I13: ND | J13: ND | K13: SQL,ETL , Data Transformation | L13: Python & Cloud exposure | M13: On-site | N13: Large | O13: =IF(ISBLANK(K13),0,IF(ISNUMBER(SEARCH("sql",K13)),1,0)) -> 1 | P13: =IF(ISBLANK(K13),0,IF(ISNUMBER(SEARCH("Python",K13)),1,0)) -> 0 | Q13: =IF(ISBLANK(K13),0,IF(ISNUMBER(SEARCH("PowerBI",K13)),1,0)) -> 0 | R13: =IF(ISBLANK(K13),0,IF(ISNUMBER(SEARCH("Tableau",K13)),1,0)) -> 0 | S13: =IF(ISBLANK(K13),0,IF(ISNUMBER(SEARCH("Excel",K13)),1,0)) -> 0 | T13: =IF(ISBLANK(K13),0,IF(ISNUMBER(SEARCH("Statistics",K13)),1,0)) -> 0 | U13: =IF(ISBLANK(K13),0,IF(ISNUMBER(SEARCH("AWS",K13)),1,0)) -> 0 | V13: =IF(ISBLANK(K13),0,IF(ISNUMBER(SEARCH("GCP",K13)),1,0)) -> 0 | W13: =IF(ISBLANK(K13),0,IF(ISNUMBER(SEARCH("NoSQL",K13)),1,0)) -> 0 | X13: =IF(ISBLANK(K13),0,IF(ISNUMBER(SEARCH("Data Modeling",K13)),1,0)) -> 0 | Y13: =IF(ISBLANK(K13),0,IF(ISNUMBER(SEARCH("Pandas",K13)),1,0)) -> 0 | Z13: =IF(ISBLANK(K13),0,IF(ISNUMBER(SEARCH("Numpy",K13)),1,0)) -> 0 | AA13: =IF(ISBLANK(K13),0,IF(ISNUMBER(SEARCH("Pyspark",K13)),1,0)) -> 0 | AB13: =IF(ISBLANK(K13),0,IF(ISNUMBER(SEARCH("Hadoop",K13)),1,0)) -> 0 | AC13: =IF(ISBLANK(K13),0,IF(ISNUMBER(SEARCH("ETL",K13)),1,0)) -> 1 | AD13: =IF(ISBLANK(K13),0,IF(ISNUMBER(SEARCH("Azure",K13)),1,0)) -> 0 | AE13: =IF(ISBLANK(K13),0,IF(ISNUMBER(SEARCH("Databricks",K13)),1,0)) -> 0 | AF13: =IF(ISBLANK(K13),0,IF(ISNUMBER(SEARCH("A/B Testing",K13)),1,0)) -> 0 | AG13: =IF(ISBLANK(K13),0,IF(ISNUMBER(SEARCH("Snowflake",K13)),1,0)) -> 0 | AH13: =IF(ISBLANK(K13),0,IF(ISNUMBER(SEARCH("Agile",K13)),1,0)) -> 0 | AI13: =IF(ISBLANK(K13),0,IF(ISNUMBER(SEARCH("Jira",K13)),1,0)) -> 0 | AJ13: =IF(ISBLANK(K13),0,IF(ISNUMBER(SEARCH("Git",K13)),1,0)) -> 0 | AK13: =IF(ISBLANK(K13),0,IF(ISNUMBER(SEARCH("Reporting",K13)),1,0)) -> 0 | AL13: =IF(ISBLANK(K13),0,IF(ISNUMBER(SEARCH("CI/CD",K13)),1,0)) -> 0 | AM13: =IF(ISBLANK(L13),0,IF(ISNUMBER(SEARCH("Python",L13)),1,0)) -> 1 | AN13: =IF(ISBLANK(L13),0,IF(ISNUMBER(SEARCH("SQL",L13)),1,0)) -> 0 | AO13: =IF(ISBLANK(L13),0,IF(ISNUMBER(SEARCH("Airflow",L13)),1,0)) -> 0 | AP13: =IF(ISBLANK(L13),0,IF(ISNUMBER(SEARCH("Kafka",L13)),1,0)) -> 0 | AQ13: =IF(ISBLANK(L13),0,IF(ISNUMBER(SEARCH("ML",L13)),1,0)) -> 0 | AR13: =IF(ISBLANK(L14),0,IF(ISNUMBER(SEARCH("ML",L14)),1,0)) -> 0 | AS13: =IF(ISBLANK(L15),0,IF(ISNUMBER(SEARCH("Docker",L15)),1,0)) -> 0 | AT13: =IF(ISBLANK(L15),0,IF(ISNUMBER(SEARCH("dbt",L15)),1,0)) -> 0 | AU13: =IF(ISBLANK(L15),0,IF(ISNUMBER(SEARCH("AWS",L15)),1,0)) -> 0 | AV13: =IF(ISBLANK(L15),0,IF(ISNUMBER(SEARCH("GCP",L15)),1,0)) -> 0 | AW13: =IF(ISBLANK(L15),0,IF(ISNUMBER(SEARCH("Azure",L15)),1,0)) -> 0 | AX13: =IF(ISBLANK(M15),0,IF(ISNUMBER(SEARCH("Tableau",L15)),1,0)) -> 0 | AY13: =IF(ISBLANK(N15),0,IF(ISNUMBER(SEARCH("PowerBI",L15)),1,0)) -> 0 | AZ13: Fulltime
A14: 13 | B14: 46178 | C14: LinkedIn | D14: Data Analyst | E14: CoffeeBeans | F14: Bengaluru | G14: 7 | H14: 10 | I14: ND | J14: ND | K14: Advanced SQL , PowerBI , Github | L14: Azure data systems, ETL pipelines, Agile/Scrum | M14: On-site | N14: Medium | O14: =IF(ISBLANK(K14),0,IF(ISNUMBER(SEARCH("sql",K14)),1,0)) -> 1 | P14: =IF(ISBLANK(K14),0,IF(ISNUMBER(SEARCH("Python",K14)),1,0)) -> 0 | Q14: =IF(ISBLANK(K14),0,IF(ISNUMBER(SEARCH("PowerBI",K14)),1,0)) -> 1 | R14: =IF(ISBLANK(K14),0,IF(ISNUMBER(SEARCH("Tableau",K14)),1,0)) -> 0 | S14: =IF(ISBLANK(K14),0,IF(ISNUMBER(SEARCH("Excel",K14)),1,0)) -> 0 | T14: =IF(ISBLANK(K14),0,IF(ISNUMBER(SEARCH("Statistics",K14)),1,0)) -> 0 | U14: =IF(ISBLANK(K14),0,IF(ISNUMBER(SEARCH("AWS",K14)),1,0)) -> 0 | V14: =IF(ISBLANK(K14),0,IF(ISNUMBER(SEARCH("GCP",K14)),1,0)) -> 0 | W14: =IF(ISBLANK(K14),0,IF(ISNUMBER(SEARCH("NoSQL",K14)),1,0)) -> 0 | X14: =IF(ISBLANK(K14),0,IF(ISNUMBER(SEARCH("Data Modeling",K14)),1,0)) -> 0 | Y14: =IF(ISBLANK(K14),0,IF(ISNUMBER(SEARCH("Pandas",K14)),1,0)) -> 0 | Z14: =IF(ISBLANK(K14),0,IF(ISNUMBER(SEARCH("Numpy",K14)),1,0)) -> 0 | AA14: =IF(ISBLANK(K14),0,IF(ISNUMBER(SEARCH("Pyspark",K14)),1,0)) -> 0 | AB14: =IF(ISBLANK(K14),0,IF(ISNUMBER(SEARCH("Hadoop",K14)),1,0)) -> 0 | AC14: =IF(ISBLANK(K14),0,IF(ISNUMBER(SEARCH("ETL",K14)),1,0)) -> 0 | AD14: =IF(ISBLANK(K14),0,IF(ISNUMBER(SEARCH("Azure",K14)),1,0)) -> 0 | AE14: =IF(ISBLANK(K14),0,IF(ISNUMBER(SEARCH("Databricks",K14)),1,0)) -> 0 | AF14: =IF(ISBLANK(K14),0,IF(ISNUMBER(SEARCH("A/B Testing",K14)),1,0)) -> 0 | AG14: =IF(ISBLANK(K14),0,IF(ISNUMBER(SEARCH("Snowflake",K14)),1,0)) -> 0 | AH14: =IF(ISBLANK(K14),0,IF(ISNUMBER(SEARCH("Agile",K14)),1,0)) -> 0 | AI14: =IF(ISBLANK(K14),0,IF(ISNUMBER(SEARCH("Jira",K14)),1,0)) -> 0 | AJ14: =IF(ISBLANK(K14),0,IF(ISNUMBER(SEARCH("Git",K14)),1,0)) -> 1 | AK14: =IF(ISBLANK(K14),0,IF(ISNUMBER(SEARCH("Reporting",K14)),1,0)) -> 0 | AL14: =IF(ISBLANK(K14),0,IF(ISNUMBER(SEARCH("CI/CD",K14)),1,0)) -> 0 | AM14: =IF(ISBLANK(L14),0,IF(ISNUMBER(SEARCH("Python",L14)),1,0)) -> 0 | AN14: =IF(ISBLANK(L14),0,IF(ISNUMBER(SEARCH("SQL",L14)),1,0)) -> 0 | AO14: =IF(ISBLANK(L14),0,IF(ISNUMBER(SEARCH("Airflow",L14)),1,0)) -> 0 | AP14: =IF(ISBLANK(L14),0,IF(ISNUMBER(SEARCH("Kafka",L14)),1,0)) -> 0 | AQ14: =IF(ISBLANK(L14),0,IF(ISNUMBER(SEARCH("ML",L14)),1,0)) -> 0 | AR14: =IF(ISBLANK(L15),0,IF(ISNUMBER(SEARCH("ML",L15)),1,0)) -> 0 | AS14: =IF(ISBLANK(L16),0,IF(ISNUMBER(SEARCH("Docker",L16)),1,0)) -> 0 | AT14: =IF(ISBLANK(L16),0,IF(ISNUMBER(SEARCH("dbt",L16)),1,0)) -> 0 | AU14: =IF(ISBLANK(L16),0,IF(ISNUMBER(SEARCH("AWS",L16)),1,0)) -> 0 | AV14: =IF(ISBLANK(L16),0,IF(ISNUMBER(SEARCH("GCP",L16)),1,0)) -> 0 | AW14: =IF(ISBLANK(L16),0,IF(ISNUMBER(SEARCH("Azure",L16)),1,0)) -> 0 | AX14: =IF(ISBLANK(M16),0,IF(ISNUMBER(SEARCH("Tableau",L16)),1,0)) -> 0 | AY14: =IF(ISBLANK(N16),0,IF(ISNUMBER(SEARCH("PowerBI",L16)),1,0)) -> 0 | AZ14: Fulltime
A15: 14 | B15: 46178 | C15: LinkedIn | D15: Data Analyst | E15: Skeps | F15: Gurgaon | G15: 2 | H15: ND | I15: ND | J15: ND | K15: Excel , SQL, Python , Dashboarding Tools(Tableau, Metabase etc), Statistics,Pandas, Numpy , Scikit learn,Seaborn | L15: None | M15: On-site | N15: Startup | O15: =IF(ISBLANK(K15),0,IF(ISNUMBER(SEARCH("sql",K15)),1,0)) -> 1 | P15: =IF(ISBLANK(K15),0,IF(ISNUMBER(SEARCH("Python",K15)),1,0)) -> 1 | Q15: =IF(ISBLANK(K15),0,IF(ISNUMBER(SEARCH("PowerBI",K15)),1,0)) -> 0 | R15: =IF(ISBLANK(K15),0,IF(ISNUMBER(SEARCH("Tableau",K15)),1,0)) -> 1 | S15: =IF(ISBLANK(K15),0,IF(ISNUMBER(SEARCH("Excel",K15)),1,0)) -> 1 | T15: =IF(ISBLANK(K15),0,IF(ISNUMBER(SEARCH("Statistics",K15)),1,0)) -> 1 | U15: =IF(ISBLANK(K15),0,IF(ISNUMBER(SEARCH("AWS",K15)),1,0)) -> 0 | V15: =IF(ISBLANK(K15),0,IF(ISNUMBER(SEARCH("GCP",K15)),1,0)) -> 0 | W15: =IF(ISBLANK(K15),0,IF(ISNUMBER(SEARCH("NoSQL",K15)),1,0)) -> 0 | X15: =IF(ISBLANK(K15),0,IF(ISNUMBER(SEARCH("Data Modeling",K15)),1,0)) -> 0 | Y15: =IF(ISBLANK(K15),0,IF(ISNUMBER(SEARCH("Pandas",K15)),1,0)) -> 1 | Z15: =IF(ISBLANK(K15),0,IF(ISNUMBER(SEARCH("Numpy",K15)),1,0)) -> 1 | AA15: =IF(ISBLANK(K15),0,IF(ISNUMBER(SEARCH("Pyspark",K15)),1,0)) -> 0 | AB15: =IF(ISBLANK(K15),0,IF(ISNUMBER(SEARCH("Hadoop",K15)),1,0)) -> 0 | AC15: =IF(ISBLANK(K15),0,IF(ISNUMBER(SEARCH("ETL",K15)),1,0)) -> 0 | AD15: =IF(ISBLANK(K15),0,IF(ISNUMBER(SEARCH("Azure",K15)),1,0)) -> 0 | AE15: =IF(ISBLANK(K15),0,IF(ISNUMBER(SEARCH("Databricks",K15)),1,0)) -> 0 | AF15: =IF(ISBLANK(K15),0,IF(ISNUMBER(SEARCH("A/B Testing",K15)),1,0)) -> 0 | AG15: =IF(ISBLANK(K15),0,IF(ISNUMBER(SEARCH("Snowflake",K15)),1,0)) -> 0 | AH15: =IF(ISBLANK(K15),0,IF(ISNUMBER(SEARCH("Agile",K15)),1,0)) -> 0 | AI15: =IF(ISBLANK(K15),0,IF(ISNUMBER(SEARCH("Jira",K15)),1,0)) -> 0 | AJ15: =IF(ISBLANK(K15),0,IF(ISNUMBER(SEARCH("Git",K15)),1,0)) -> 0 | AK15: =IF(ISBLANK(K15),0,IF(ISNUMBER(SEARCH("Reporting",K15)),1,0)) -> 0 | AL15: =IF(ISBLANK(K15),0,IF(ISNUMBER(SEARCH("CI/CD",K15)),1,0)) -> 0 | AM15: =IF(ISBLANK(L15),0,IF(ISNUMBER(SEARCH("Python",L15)),1,0)) -> 0 | AN15: =IF(ISBLANK(L15),0,IF(ISNUMBER(SEARCH("SQL",L15)),1,0)) -> 0 | AO15: =IF(ISBLANK(L15),0,IF(ISNUMBER(SEARCH("Airflow",L15)),1,0)) -> 0 | AP15: =IF(ISBLANK(L15),0,IF(ISNUMBER(SEARCH("Kafka",L15)),1,0)) -> 0 | AQ15: =IF(ISBLANK(L15),0,IF(ISNUMBER(SEARCH("ML",L15)),1,0)) -> 0 | AR15: =IF(ISBLANK(L16),0,IF(ISNUMBER(SEARCH("ML",L16)),1,0)) -> 0 | AS15: =IF(ISBLANK(L17),0,IF(ISNUMBER(SEARCH("Docker",L17)),1,0)) -> 0 | AT15: =IF(ISBLANK(L17),0,IF(ISNUMBER(SEARCH("dbt",L17)),1,0)) -> 0 | AU15: =IF(ISBLANK(L17),0,IF(ISNUMBER(SEARCH("AWS",L17)),1,0)) -> 1 | AV15: =IF(ISBLANK(L17),0,IF(ISNUMBER(SEARCH("GCP",L17)),1,0)) -> 1 | AW15: =IF(ISBLANK(L17),0,IF(ISNUMBER(SEARCH("Azure",L17)),1,0)) -> 1 | AX15: =IF(ISBLANK(M17),0,IF(ISNUMBER(SEARCH("Tableau",L17)),1,0)) -> 0 | AY15: =IF(ISBLANK(N17),0,IF(ISNUMBER(SEARCH("PowerBI",L17)),1,0)) -> 0 | AZ15: Fulltime
A16: 15 | B16: 46178 | C16: LinkedIn | D16: Data Analyst | E16: Prudent Technologies and Consulting Inc | F16: Hyderabad | G16: 2 | H16: 5 | I16: ND | J16: ND | K16: MySQL , DAX , PowerBI, Data Analysis | L16: None | M16: On-site | N16: Large | O16: =IF(ISBLANK(K16),0,IF(ISNUMBER(SEARCH("sql",K16)),1,0)) -> 1 | P16: =IF(ISBLANK(K16),0,IF(ISNUMBER(SEARCH("Python",K16)),1,0)) -> 0 | Q16: =IF(ISBLANK(K16),0,IF(ISNUMBER(SEARCH("PowerBI",K16)),1,0)) -> 1 | R16: =IF(ISBLANK(K16),0,IF(ISNUMBER(SEARCH("Tableau",K16)),1,0)) -> 0 | S16: =IF(ISBLANK(K16),0,IF(ISNUMBER(SEARCH("Excel",K16)),1,0)) -> 0 | T16: =IF(ISBLANK(K16),0,IF(ISNUMBER(SEARCH("Statistics",K16)),1,0)) -> 0 | U16: =IF(ISBLANK(K16),0,IF(ISNUMBER(SEARCH("AWS",K16)),1,0)) -> 0 | V16: =IF(ISBLANK(K16),0,IF(ISNUMBER(SEARCH("GCP",K16)),1,0)) -> 0 | W16: =IF(ISBLANK(K16),0,IF(ISNUMBER(SEARCH("NoSQL",K16)),1,0)) -> 0 | X16: =IF(ISBLANK(K16),0,IF(ISNUMBER(SEARCH("Data Modeling",K16)),1,0)) -> 0 | Y16: =IF(ISBLANK(K16),0,IF(ISNUMBER(SEARCH("Pandas",K16)),1,0)) -> 0 | Z16: =IF(ISBLANK(K16),0,IF(ISNUMBER(SEARCH("Numpy",K16)),1,0)) -> 0 | AA16: =IF(ISBLANK(K16),0,IF(ISNUMBER(SEARCH("Pyspark",K16)),1,0)) -> 0 | AB16: =IF(ISBLANK(K16),0,IF(ISNUMBER(SEARCH("Hadoop",K16)),1,0)) -> 0 | AC16: =IF(ISBLANK(K16),0,IF(ISNUMBER(SEARCH("ETL",K16)),1,0)) -> 0 | AD16: =IF(ISBLANK(K16),0,IF(ISNUMBER(SEARCH("Azure",K16)),1,0)) -> 0 | AE16: =IF(ISBLANK(K16),0,IF(ISNUMBER(SEARCH("Databricks",K16)),1,0)) -> 0 | AF16: =IF(ISBLANK(K16),0,IF(ISNUMBER(SEARCH("A/B Testing",K16)),1,0)) -> 0 | AG16: =IF(ISBLANK(K16),0,IF(ISNUMBER(SEARCH("Snowflake",K16)),1,0)) -> 0 | AH16: =IF(ISBLANK(K16),0,IF(ISNUMBER(SEARCH("Agile",K16)),1,0)) -> 0 | AI16: =IF(ISBLANK(K16),0,IF(ISNUMBER(SEARCH("Jira",K16)),1,0)) -> 0 | AJ16: =IF(ISBLANK(K16),0,IF(ISNUMBER(SEARCH("Git",K16)),1,0)) -> 0 | AK16: =IF(ISBLANK(K16),0,IF(ISNUMBER(SEARCH("Reporting",K16)),1,0)) -> 0 | AL16: =IF(ISBLANK(K16),0,IF(ISNUMBER(SEARCH("CI/CD",K16)),1,0)) -> 0 | AM16: =IF(ISBLANK(L16),0,IF(ISNUMBER(SEARCH("Python",L16)),1,0)) -> 0 | AN16: =IF(ISBLANK(L16),0,IF(ISNUMBER(SEARCH("SQL",L16)),1,0)) -> 0 | AO16: =IF(ISBLANK(L16),0,IF(ISNUMBER(SEARCH("Airflow",L16)),1,0)) -> 0 | AP16: =IF(ISBLANK(L16),0,IF(ISNUMBER(SEARCH("Kafka",L16)),1,0)) -> 0 | AQ16: =IF(ISBLANK(L16),0,IF(ISNUMBER(SEARCH("ML",L16)),1,0)) -> 0 | AR16: =IF(ISBLANK(L17),0,IF(ISNUMBER(SEARCH("ML",L17)),1,0)) -> 0 | AS16: =IF(ISBLANK(L18),0,IF(ISNUMBER(SEARCH("Docker",L18)),1,0)) -> 0 | AT16: =IF(ISBLANK(L18),0,IF(ISNUMBER(SEARCH("dbt",L18)),1,0)) -> 0 | AU16: =IF(ISBLANK(L18),0,IF(ISNUMBER(SEARCH("AWS",L18)),1,0)) -> 0 | AV16: =IF(ISBLANK(L18),0,IF(ISNUMBER(SEARCH("GCP",L18)),1,0)) -> 0 | AW16: =IF(ISBLANK(L18),0,IF(ISNUMBER(SEARCH("Azure",L18)),1,0)) -> 0 | AX16: =IF(ISBLANK(M18),0,IF(ISNUMBER(SEARCH("Tableau",L18)),1,0)) -> 0 | AY16: =IF(ISBLANK(N18),0,IF(ISNUMBER(SEARCH("PowerBI",L18)),1,0)) -> 0 | AZ16: Fulltime
A17: 16 | B17: 46178 | C17: LinkedIn | D17: Data Analyst | E17: Call Quest Solutions | F17: Pune | G17: ND | H17: ND | I17: ND | J17: ND | K17: SQL , Excel , Python /R, Data visualization tools | L17: AWS/Azure/GCP, Predictive analytics, Data warehouse concepts | M17: On-site | N17: Medium | O17: =IF(ISBLANK(K17),0,IF(ISNUMBER(SEARCH("sql",K17)),1,0)) -> 1 | P17: =IF(ISBLANK(K17),0,IF(ISNUMBER(SEARCH("Python",K17)),1,0)) -> 1 | Q17: =IF(ISBLANK(K17),0,IF(ISNUMBER(SEARCH("PowerBI",K17)),1,0)) -> 0 | R17: =IF(ISBLANK(K17),0,IF(ISNUMBER(SEARCH("Tableau",K17)),1,0)) -> 0 | S17: =IF(ISBLANK(K17),0,IF(ISNUMBER(SEARCH("Excel",K17)),1,0)) -> 1 | T17: =IF(ISBLANK(K17),0,IF(ISNUMBER(SEARCH("Statistics",K17)),1,0)) -> 0 | U17: =IF(ISBLANK(K17),0,IF(ISNUMBER(SEARCH("AWS",K17)),1,0)) -> 0 | V17: =IF(ISBLANK(K17),0,IF(ISNUMBER(SEARCH("GCP",K17)),1,0)) -> 0 | W17: =IF(ISBLANK(K17),0,IF(ISNUMBER(SEARCH("NoSQL",K17)),1,0)) -> 0 | X17: =IF(ISBLANK(K17),0,IF(ISNUMBER(SEARCH("Data Modeling",K17)),1,0)) -> 0 | Y17: =IF(ISBLANK(K17),0,IF(ISNUMBER(SEARCH("Pandas",K17)),1,0)) -> 0 | Z17: =IF(ISBLANK(K17),0,IF(ISNUMBER(SEARCH("Numpy",K17)),1,0)) -> 0 | AA17: =IF(ISBLANK(K17),0,IF(ISNUMBER(SEARCH("Pyspark",K17)),1,0)) -> 0 | AB17: =IF(ISBLANK(K17),0,IF(ISNUMBER(SEARCH("Hadoop",K17)),1,0)) -> 0 | AC17: =IF(ISBLANK(K17),0,IF(ISNUMBER(SEARCH("ETL",K17)),1,0)) -> 0 | AD17: =IF(ISBLANK(K17),0,IF(ISNUMBER(SEARCH("Azure",K17)),1,0)) -> 0 | AE17: =IF(ISBLANK(K17),0,IF(ISNUMBER(SEARCH("Databricks",K17)),1,0)) -> 0 | AF17: =IF(ISBLANK(K17),0,IF(ISNUMBER(SEARCH("A/B Testing",K17)),1,0)) -> 0 | AG17: =IF(ISBLANK(K17),0,IF(ISNUMBER(SEARCH("Snowflake",K17)),1,0)) -> 0 | AH17: =IF(ISBLANK(K17),0,IF(ISNUMBER(SEARCH("Agile",K17)),1,0)) -> 0 | AI17: =IF(ISBLANK(K17),0,IF(ISNUMBER(SEARCH("Jira",K17)),1,0)) -> 0 | AJ17: =IF(ISBLANK(K17),0,IF(ISNUMBER(SEARCH("Git",K17)),1,0)) -> 0 | AK17: =IF(ISBLANK(K17),0,IF(ISNUMBER(SEARCH("Reporting",K17)),1,0)) -> 0 | AL17: =IF(ISBLANK(K17),0,IF(ISNUMBER(SEARCH("CI/CD",K17)),1,0)) -> 0 | AM17: =IF(ISBLANK(L17),0,IF(ISNUMBER(SEARCH("Python",L17)),1,0)) -> 0 | AN17: =IF(ISBLANK(L17),0,IF(ISNUMBER(SEARCH("SQL",L17)),1,0)) -> 0 | AO17: =IF(ISBLANK(L17),0,IF(ISNUMBER(SEARCH("Airflow",L17)),1,0)) -> 0 | AP17: =IF(ISBLANK(L17),0,IF(ISNUMBER(SEARCH("Kafka",L17)),1,0)) -> 0 | AQ17: =IF(ISBLANK(L17),0,IF(ISNUMBER(SEARCH("ML",L17)),1,0)) -> 0 | AR17: =IF(ISBLANK(L18),0,IF(ISNUMBER(SEARCH("ML",L18)),1,0)) -> 0 | AS17: =IF(ISBLANK(L19),0,IF(ISNUMBER(SEARCH("Docker",L19)),1,0)) -> 0 | AT17: =IF(ISBLANK(L19),0,IF(ISNUMBER(SEARCH("dbt",L19)),1,0)) -> 0 | AU17: =IF(ISBLANK(L19),0,IF(ISNUMBER(SEARCH("AWS",L19)),1,0)) -> 0 | AV17: =IF(ISBLANK(L19),0,IF(ISNUMBER(SEARCH("GCP",L19)),1,0)) -> 0 | AW17: =IF(ISBLANK(L19),0,IF(ISNUMBER(SEARCH("Azure",L19)),1,0)) -> 0 | AX17: =IF(ISBLANK(M19),0,IF(ISNUMBER(SEARCH("Tableau",L19)),1,0)) -> 0 | AY17: =IF(ISBLANK(N19),0,IF(ISNUMBER(SEARCH("PowerBI",L19)),1,0)) -> 0 | AZ17: Fulltime
A18: 17 | B18: 46178 | C18: LinkedIn | D18: Data Analyst | E18: Infovision | F18: Bengaluru | G18: ND | H18: ND | I18: ND | J18: ND | K18: Python,SQL, Git, Statistics, Advanced Excel, Data visualization tools | L18: None | M18: On-site | N18: Medium | O18: =IF(ISBLANK(K18),0,IF(ISNUMBER(SEARCH("sql",K18)),1,0)) -> 1 | P18: =IF(ISBLANK(K18),0,IF(ISNUMBER(SEARCH("Python",K18)),1,0)) -> 1 | Q18: =IF(ISBLANK(K18),0,IF(ISNUMBER(SEARCH("PowerBI",K18)),1,0)) -> 0 | R18: =IF(ISBLANK(K18),0,IF(ISNUMBER(SEARCH("Tableau",K18)),1,0)) -> 0 | S18: =IF(ISBLANK(K18),0,IF(ISNUMBER(SEARCH("Excel",K18)),1,0)) -> 1 | T18: =IF(ISBLANK(K18),0,IF(ISNUMBER(SEARCH("Statistics",K18)),1,0)) -> 1 | U18: =IF(ISBLANK(K18),0,IF(ISNUMBER(SEARCH("AWS",K18)),1,0)) -> 0 | V18: =IF(ISBLANK(K18),0,IF(ISNUMBER(SEARCH("GCP",K18)),1,0)) -> 0 | W18: =IF(ISBLANK(K18),0,IF(ISNUMBER(SEARCH("NoSQL",K18)),1,0)) -> 0 | X18: =IF(ISBLANK(K18),0,IF(ISNUMBER(SEARCH("Data Modeling",K18)),1,0)) -> 0 | Y18: =IF(ISBLANK(K18),0,IF(ISNUMBER(SEARCH("Pandas",K18)),1,0)) -> 0 | Z18: =IF(ISBLANK(K18),0,IF(ISNUMBER(SEARCH("Numpy",K18)),1,0)) -> 0 | AA18: =IF(ISBLANK(K18),0,IF(ISNUMBER(SEARCH("Pyspark",K18)),1,0)) -> 0 | AB18: =IF(ISBLANK(K18),0,IF(ISNUMBER(SEARCH("Hadoop",K18)),1,0)) -> 0 | AC18: =IF(ISBLANK(K18),0,IF(ISNUMBER(SEARCH("ETL",K18)),1,0)) -> 0 | AD18: =IF(ISBLANK(K18),0,IF(ISNUMBER(SEARCH("Azure",K18)),1,0)) -> 0 | AE18: =IF(ISBLANK(K18),0,IF(ISNUMBER(SEARCH("Databricks",K18)),1,0)) -> 0 | AF18: =IF(ISBLANK(K18),0,IF(ISNUMBER(SEARCH("A/B Testing",K18)),1,0)) -> 0 | AG18: =IF(ISBLANK(K18),0,IF(ISNUMBER(SEARCH("Snowflake",K18)),1,0)) -> 0 | AH18: =IF(ISBLANK(K18),0,IF(ISNUMBER(SEARCH("Agile",K18)),1,0)) -> 0 | AI18: =IF(ISBLANK(K18),0,IF(ISNUMBER(SEARCH("Jira",K18)),1,0)) -> 0 | AJ18: =IF(ISBLANK(K18),0,IF(ISNUMBER(SEARCH("Git",K18)),1,0)) -> 1 | AK18: =IF(ISBLANK(K18),0,IF(ISNUMBER(SEARCH("Reporting",K18)),1,0)) -> 0 | AL18: =IF(ISBLANK(K18),0,IF(ISNUMBER(SEARCH("CI/CD",K18)),1,0)) -> 0 | AM18: =IF(ISBLANK(L18),0,IF(ISNUMBER(SEARCH("Python",L18)),1,0)) -> 0 | AN18: =IF(ISBLANK(L18),0,IF(ISNUMBER(SEARCH("SQL",L18)),1,0)) -> 0 | AO18: =IF(ISBLANK(L18),0,IF(ISNUMBER(SEARCH("Airflow",L18)),1,0)) -> 0 | AP18: =IF(ISBLANK(L18),0,IF(ISNUMBER(SEARCH("Kafka",L18)),1,0)) -> 0 | AQ18: =IF(ISBLANK(L18),0,IF(ISNUMBER(SEARCH("ML",L18)),1,0)) -> 0 | AR18: =IF(ISBLANK(L19),0,IF(ISNUMBER(SEARCH("ML",L19)),1,0)) -> 0 | AS18: =IF(ISBLANK(L20),0,IF(ISNUMBER(SEARCH("Docker",L20)),1,0)) -> 0 | AT18: =IF(ISBLANK(L20),0,IF(ISNUMBER(SEARCH("dbt",L20)),1,0)) -> 0 | AU18: =IF(ISBLANK(L20),0,IF(ISNUMBER(SEARCH("AWS",L20)),1,0)) -> 0 | AV18: =IF(ISBLANK(L20),0,IF(ISNUMBER(SEARCH("GCP",L20)),1,0)) -> 1 | AW18: =IF(ISBLANK(L20),0,IF(ISNUMBER(SEARCH("Azure",L20)),1,0)) -> 0 | AX18: =IF(ISBLANK(M20),0,IF(ISNUMBER(SEARCH("Tableau",L20)),1,0)) -> 0 | AY18: =IF(ISBLANK(N20),0,IF(ISNUMBER(SEARCH("PowerBI",L20)),1,0)) -> 0 | AZ18: Fulltime
A19: 18 | B19: 46178 | C19: LinkedIn | D19: Data Engineer | E19: Qualcomm | F19: Bengaluru | G19: 3 | H19: 5 | I19: ND | J19: ND | K19: Data Modeling, Data Analysis, Python , Advanced SQL , NpSQL , DB Unix Shell scripts | L19: None | M19: On-site | N19: Large | O19: =IF(ISBLANK(K19),0,IF(ISNUMBER(SEARCH("sql",K19)),1,0)) -> 1 | P19: =IF(ISBLANK(K19),0,IF(ISNUMBER(SEARCH("Python",K19)),1,0)) -> 1 | Q19: =IF(ISBLANK(K19),0,IF(ISNUMBER(SEARCH("PowerBI",K19)),1,0)) -> 0 | R19: =IF(ISBLANK(K19),0,IF(ISNUMBER(SEARCH("Tableau",K19)),1,0)) -> 0 | S19: =IF(ISBLANK(K19),0,IF(ISNUMBER(SEARCH("Excel",K19)),1,0)) -> 0 | T19: =IF(ISBLANK(K19),0,IF(ISNUMBER(SEARCH("Statistics",K19)),1,0)) -> 0 | U19: =IF(ISBLANK(K19),0,IF(ISNUMBER(SEARCH("AWS",K19)),1,0)) -> 0 | V19: =IF(ISBLANK(K19),0,IF(ISNUMBER(SEARCH("GCP",K19)),1,0)) -> 0 | W19: =IF(ISBLANK(K19),0,IF(ISNUMBER(SEARCH("NoSQL",K19)),1,0)) -> 0 | X19: =IF(ISBLANK(K19),0,IF(ISNUMBER(SEARCH("Data Modeling",K19)),1,0)) -> 1 | Y19: =IF(ISBLANK(K19),0,IF(ISNUMBER(SEARCH("Pandas",K19)),1,0)) -> 0 | Z19: =IF(ISBLANK(K19),0,IF(ISNUMBER(SEARCH("Numpy",K19)),1,0)) -> 0 | AA19: =IF(ISBLANK(K19),0,IF(ISNUMBER(SEARCH("Pyspark",K19)),1,0)) -> 0 | AB19: =IF(ISBLANK(K19),0,IF(ISNUMBER(SEARCH("Hadoop",K19)),1,0)) -> 0 | AC19: =IF(ISBLANK(K19),0,IF(ISNUMBER(SEARCH("ETL",K19)),1,0)) -> 0 | AD19: =IF(ISBLANK(K19),0,IF(ISNUMBER(SEARCH("Azure",K19)),1,0)) -> 0 | AE19: =IF(ISBLANK(K19),0,IF(ISNUMBER(SEARCH("Databricks",K19)),1,0)) -> 0 | AF19: =IF(ISBLANK(K19),0,IF(ISNUMBER(SEARCH("A/B Testing",K19)),1,0)) -> 0 | AG19: =IF(ISBLANK(K19),0,IF(ISNUMBER(SEARCH("Snowflake",K19)),1,0)) -> 0 | AH19: =IF(ISBLANK(K19),0,IF(ISNUMBER(SEARCH("Agile",K19)),1,0)) -> 0 | AI19: =IF(ISBLANK(K19),0,IF(ISNUMBER(SEARCH("Jira",K19)),1,0)) -> 0 | AJ19: =IF(ISBLANK(K19),0,IF(ISNUMBER(SEARCH("Git",K19)),1,0)) -> 0 | AK19: =IF(ISBLANK(K19),0,IF(ISNUMBER(SEARCH("Reporting",K19)),1,0)) -> 0 | AL19: =IF(ISBLANK(K19),0,IF(ISNUMBER(SEARCH("CI/CD",K19)),1,0)) -> 0 | AM19: =IF(ISBLANK(L19),0,IF(ISNUMBER(SEARCH("Python",L19)),1,0)) -> 0 | AN19: =IF(ISBLANK(L19),0,IF(ISNUMBER(SEARCH("SQL",L19)),1,0)) -> 0 | AO19: =IF(ISBLANK(L19),0,IF(ISNUMBER(SEARCH("Airflow",L19)),1,0)) -> 0 | AP19: =IF(ISBLANK(L19),0,IF(ISNUMBER(SEARCH("Kafka",L19)),1,0)) -> 0 | AQ19: =IF(ISBLANK(L19),0,IF(ISNUMBER(SEARCH("ML",L19)),1,0)) -> 0 | AR19: =IF(ISBLANK(L20),0,IF(ISNUMBER(SEARCH("ML",L20)),1,0)) -> 0 | AS19: =IF(ISBLANK(L21),0,IF(ISNUMBER(SEARCH("Docker",L21)),1,0)) -> 0 | AT19: =IF(ISBLANK(L21),0,IF(ISNUMBER(SEARCH("dbt",L21)),1,0)) -> 0 | AU19: =IF(ISBLANK(L21),0,IF(ISNUMBER(SEARCH("AWS",L21)),1,0)) -> 1 | AV19: =IF(ISBLANK(L21),0,IF(ISNUMBER(SEARCH("GCP",L21)),1,0)) -> 1 | AW19: =IF(ISBLANK(L21),0,IF(ISNUMBER(SEARCH("Azure",L21)),1,0)) -> 0 | AX19: =IF(ISBLANK(M21),0,IF(ISNUMBER(SEARCH("Tableau",L21)),1,0)) -> 0 | AY19: =IF(ISBLANK(N21),0,IF(ISNUMBER(SEARCH("PowerBI",L21)),1,0)) -> 0 | AZ19: Fulltime
A20: 19 | B20: 46178 | C20: LinkedIn | D20: Data Engineer | E20: Impetus | F20: Gurgaon | G20: 4 | H20: 6 | I20: ND | J20: ND | K20: PySpark, Hadoop, Hive, Python , Bash, SQL, Data warehousing | L20: GCP sevices such as bigquery, dataflow etc, Airflow | M20: On-site | N20: Medium | O20: =IF(ISBLANK(K20),0,IF(ISNUMBER(SEARCH("sql",K20)),1,0)) -> 1 | P20: =IF(ISBLANK(K20),0,IF(ISNUMBER(SEARCH("Python",K20)),1,0)) -> 1 | Q20: =IF(ISBLANK(K20),0,IF(ISNUMBER(SEARCH("PowerBI",K20)),1,0)) -> 0 | R20: =IF(ISBLANK(K20),0,IF(ISNUMBER(SEARCH("Tableau",K20)),1,0)) -> 0 | S20: =IF(ISBLANK(K20),0,IF(ISNUMBER(SEARCH("Excel",K20)),1,0)) -> 0 | T20: =IF(ISBLANK(K20),0,IF(ISNUMBER(SEARCH("Statistics",K20)),1,0)) -> 0 | U20: =IF(ISBLANK(K20),0,IF(ISNUMBER(SEARCH("AWS",K20)),1,0)) -> 0 | V20: =IF(ISBLANK(K20),0,IF(ISNUMBER(SEARCH("GCP",K20)),1,0)) -> 0 | W20: =IF(ISBLANK(K20),0,IF(ISNUMBER(SEARCH("NoSQL",K20)),1,0)) -> 0 | X20: =IF(ISBLANK(K20),0,IF(ISNUMBER(SEARCH("Data Modeling",K20)),1,0)) -> 0 | Y20: =IF(ISBLANK(K20),0,IF(ISNUMBER(SEARCH("Pandas",K20)),1,0)) -> 0 | Z20: =IF(ISBLANK(K20),0,IF(ISNUMBER(SEARCH("Numpy",K20)),1,0)) -> 0 | AA20: =IF(ISBLANK(K20),0,IF(ISNUMBER(SEARCH("Pyspark",K20)),1,0)) -> 1 | AB20: =IF(ISBLANK(K20),0,IF(ISNUMBER(SEARCH("Hadoop",K20)),1,0)) -> 1 | AC20: =IF(ISBLANK(K20),0,IF(ISNUMBER(SEARCH("ETL",K20)),1,0)) -> 0 | AD20: =IF(ISBLANK(K20),0,IF(ISNUMBER(SEARCH("Azure",K20)),1,0)) -> 0 | AE20: =IF(ISBLANK(K20),0,IF(ISNUMBER(SEARCH("Databricks",K20)),1,0)) -> 0 | AF20: =IF(ISBLANK(K20),0,IF(ISNUMBER(SEARCH("A/B Testing",K20)),1,0)) -> 0 | AG20: =IF(ISBLANK(K20),0,IF(ISNUMBER(SEARCH("Snowflake",K20)),1,0)) -> 0 | AH20: =IF(ISBLANK(K20),0,IF(ISNUMBER(SEARCH("Agile",K20)),1,0)) -> 0 | AI20: =IF(ISBLANK(K20),0,IF(ISNUMBER(SEARCH("Jira",K20)),1,0)) -> 0 | AJ20: =IF(ISBLANK(K20),0,IF(ISNUMBER(SEARCH("Git",K20)),1,0)) -> 0 | AK20: =IF(ISBLANK(K20),0,IF(ISNUMBER(SEARCH("Reporting",K20)),1,0)) -> 0 | AL20: =IF(ISBLANK(K20),0,IF(ISNUMBER(SEARCH("CI/CD",K20)),1,0)) -> 0 | AM20: =IF(ISBLANK(L20),0,IF(ISNUMBER(SEARCH("Python",L20)),1,0)) -> 0 | AN20: =IF(ISBLANK(L20),0,IF(ISNUMBER(SEARCH("SQL",L20)),1,0)) -> 0 | AO20: =IF(ISBLANK(L20),0,IF(ISNUMBER(SEARCH("Airflow",L20)),1,0)) -> 1 | AP20: =IF(ISBLANK(L20),0,IF(ISNUMBER(SEARCH("Kafka",L20)),1,0)) -> 0 | AQ20: =IF(ISBLANK(L20),0,IF(ISNUMBER(SEARCH("ML",L20)),1,0)) -> 0 | AR20: =IF(ISBLANK(L21),0,IF(ISNUMBER(SEARCH("ML",L21)),1,0)) -> 0 | AS20: =IF(ISBLANK(L22),0,IF(ISNUMBER(SEARCH("Docker",L22)),1,0)) -> 0 | AT20: =IF(ISBLANK(L22),0,IF(ISNUMBER(SEARCH("dbt",L22)),1,0)) -> 0 | AU20: =IF(ISBLANK(L22),0,IF(ISNUMBER(SEARCH("AWS",L22)),1,0)) -> 0 | AV20: =IF(ISBLANK(L22),0,IF(ISNUMBER(SEARCH("GCP",L22)),1,0)) -> 0 | AW20: =IF(ISBLANK(L22),0,IF(ISNUMBER(SEARCH("Azure",L22)),1,0)) -> 0 | AX20: =IF(ISBLANK(M22),0,IF(ISNUMBER(SEARCH("Tableau",L22)),1,0)) -> 0 | AY20: =IF(ISBLANK(N22),0,IF(ISNUMBER(SEARCH("PowerBI",L22)),1,0)) -> 0 | AZ20: Fulltime
A21: 20 | B21: 46178 | C21: LinkedIn | D21: Data Engineer | E21: Bachatt | F21: Gurgaon | G21: 2 | H21: 4 | I21: ND | J21: ND | K21: SQL , PySpark , Java(or another similar language), Airflow | L21: AWS/GCP | M21: On-site | N21: Startup | O21: =IF(ISBLANK(K21),0,IF(ISNUMBER(SEARCH("sql",K21)),1,0)) -> 1 | P21: =IF(ISBLANK(K21),0,IF(ISNUMBER(SEARCH("Python",K21)),1,0)) -> 0 | Q21: =IF(ISBLANK(K21),0,IF(ISNUMBER(SEARCH("PowerBI",K21)),1,0)) -> 0 | R21: =IF(ISBLANK(K21),0,IF(ISNUMBER(SEARCH("Tableau",K21)),1,0)) -> 0 | S21: =IF(ISBLANK(K21),0,IF(ISNUMBER(SEARCH("Excel",K21)),1,0)) -> 0 | T21: =IF(ISBLANK(K21),0,IF(ISNUMBER(SEARCH("Statistics",K21)),1,0)) -> 0 | U21: =IF(ISBLANK(K21),0,IF(ISNUMBER(SEARCH("AWS",K21)),1,0)) -> 0 | V21: =IF(ISBLANK(K21),0,IF(ISNUMBER(SEARCH("GCP",K21)),1,0)) -> 0 | W21: =IF(ISBLANK(K21),0,IF(ISNUMBER(SEARCH("NoSQL",K21)),1,0)) -> 0 | X21: =IF(ISBLANK(K21),0,IF(ISNUMBER(SEARCH("Data Modeling",K21)),1,0)) -> 0 | Y21: =IF(ISBLANK(K21),0,IF(ISNUMBER(SEARCH("Pandas",K21)),1,0)) -> 0 | Z21: =IF(ISBLANK(K21),0,IF(ISNUMBER(SEARCH("Numpy",K21)),1,0)) -> 0 | AA21: =IF(ISBLANK(K21),0,IF(ISNUMBER(SEARCH("Pyspark",K21)),1,0)) -> 1 | AB21: =IF(ISBLANK(K21),0,IF(ISNUMBER(SEARCH("Hadoop",K21)),1,0)) -> 0 | AC21: =IF(ISBLANK(K21),0,IF(ISNUMBER(SEARCH("ETL",K21)),1,0)) -> 0 | AD21: =IF(ISBLANK(K21),0,IF(ISNUMBER(SEARCH("Azure",K21)),1,0)) -> 0 | AE21: =IF(ISBLANK(K21),0,IF(ISNUMBER(SEARCH("Databricks",K21)),1,0)) -> 0 | AF21: =IF(ISBLANK(K21),0,IF(ISNUMBER(SEARCH("A/B Testing",K21)),1,0)) -> 0 | AG21: =IF(ISBLANK(K21),0,IF(ISNUMBER(SEARCH("Snowflake",K21)),1,0)) -> 0 | AH21: =IF(ISBLANK(K21),0,IF(ISNUMBER(SEARCH("Agile",K21)),1,0)) -> 0 | AI21: =IF(ISBLANK(K21),0,IF(ISNUMBER(SEARCH("Jira",K21)),1,0)) -> 0 | AJ21: =IF(ISBLANK(K21),0,IF(ISNUMBER(SEARCH("Git",K21)),1,0)) -> 0 | AK21: =IF(ISBLANK(K21),0,IF(ISNUMBER(SEARCH("Reporting",K21)),1,0)) -> 0 | AL21: =IF(ISBLANK(K21),0,IF(ISNUMBER(SEARCH("CI/CD",K21)),1,0)) -> 0 | AM21: =IF(ISBLANK(L21),0,IF(ISNUMBER(SEARCH("Python",L21)),1,0)) -> 0 | AN21: =IF(ISBLANK(L21),0,IF(ISNUMBER(SEARCH("SQL",L21)),1,0)) -> 0 | AO21: =IF(ISBLANK(L21),0,IF(ISNUMBER(SEARCH("Airflow",L21)),1,0)) -> 0 | AP21: =IF(ISBLANK(L21),0,IF(ISNUMBER(SEARCH("Kafka",L21)),1,0)) -> 0 | AQ21: =IF(ISBLANK(L21),0,IF(ISNUMBER(SEARCH("ML",L21)),1,0)) -> 0 | AR21: =IF(ISBLANK(L22),0,IF(ISNUMBER(SEARCH("ML",L22)),1,0)) -> 0 | AS21: =IF(ISBLANK(L23),0,IF(ISNUMBER(SEARCH("Docker",L23)),1,0)) -> 0 | AT21: =IF(ISBLANK(L23),0,IF(ISNUMBER(SEARCH("dbt",L23)),1,0)) -> 0 | AU21: =IF(ISBLANK(L23),0,IF(ISNUMBER(SEARCH("AWS",L23)),1,0)) -> 0 | AV21: =IF(ISBLANK(L23),0,IF(ISNUMBER(SEARCH("GCP",L23)),1,0)) -> 0 | AW21: =IF(ISBLANK(L23),0,IF(ISNUMBER(SEARCH("Azure",L23)),1,0)) -> 0 | AX21: =IF(ISBLANK(M23),0,IF(ISNUMBER(SEARCH("Tableau",L23)),1,0)) -> 0 | AY21: =IF(ISBLANK(N23),0,IF(ISNUMBER(SEARCH("PowerBI",L23)),1,0)) -> 0 | AZ21: Fulltime
